Workbook
Name UPDATE: 'Data Sheet'!$E$1

Sheet Financials>>

Sheet Historicial Financials
B2: ="Historical Financial Statement-"&'Data Sheet'!B1 -> Historical Financial Statement-AVENUE SUPERMARTS LTD
B3: Years | C3: ='Data Sheet'!E16 -> 43921 | D3: ='Data Sheet'!F16 -> 44286 | E3: ='Data Sheet'!G16 -> 44651 | F3: ='Data Sheet'!H16 -> 45016 | G3: ='Data Sheet'!I16 -> 45382 | H3: ='Data Sheet'!J16 -> 45747 | I3: ='Data Sheet'!K16 -> 46112 | J3: LTM
A5: # | B5: Income Statements
B6: Sales | C6: =IFERROR('Data Sheet'!E17,0) -> 24870.2 | D6: =IFERROR('Data Sheet'!F17,0) -> 24143.06 | E6: =IFERROR('Data Sheet'!G17,0) -> 30976.27 | F6: =IFERROR('Data Sheet'!H17,0) -> 42839.56 | G6: =IFERROR('Data Sheet'!I17,0) -> 50788.83 | H6: =IFERROR('Data Sheet'!J17,0) -> 59358.05 | I6: =IFERROR('Data Sheet'!K17,0) -> 68820.74 | J6: =IFERROR(SUM(#REF!),0) -> 0
B7: Sales Growth | C7: - | D7: =IFERROR(D6/C6-1,0) -> -0.029237401 | E7: =IFERROR(E6/D6-1,0) -> 0.28302999 | F7: =IFERROR(F6/E6-1,0) -> 0.38297994 | G7: =IFERROR(G6/F6-1,0) -> 0.1855591 | H7: =IFERROR(H6/G6-1,0) -> 0.16872253 | I7: =IFERROR(I6/H6-1,0) -> 0.15941713
B9: COGS | C9: =IFERROR(SUM('Data Sheet'!E18,'Data Sheet'!E20,'Data Sheet'!E20:E22)-1*'Data Sheet'!E19,0) -> 22582.51 | D9: =IFERROR(SUM('Data Sheet'!F18,'Data Sheet'!F20,'Data Sheet'!F20:F22)-1*'Data Sheet'!F19,0) -> 22187.09 | E9: =IFERROR(SUM('Data Sheet'!G18,'Data Sheet'!G20,'Data Sheet'!G20:G22)-1*'Data Sheet'!G19,0) -> 28236.32 | F9: =IFERROR(SUM('Data Sheet'!H18,'Data Sheet'!H20,'Data Sheet'!H20:H22)-1*'Data Sheet'!H19,0) -> 38877.91 | G9: =IFERROR(SUM('Data Sheet'!I18,'Data Sheet'!I20,'Data Sheet'!I20:I22)-1*'Data Sheet'!I19,0) -> 46258.97 | H9: =IFERROR(SUM('Data Sheet'!J18,'Data Sheet'!J20,'Data Sheet'!J20:J22)-1*'Data Sheet'!J19,0) -> 54366.52 | I9: =IFERROR(SUM('Data Sheet'!K18,'Data Sheet'!K20,'Data Sheet'!K20:K22)-1*'Data Sheet'!K19,0) -> 60001.21 | J9: =IFERROR(SUM('Data Sheet'!H43:K43),0) -> 65868.68
B10: COGS % Sales | C10: =IFERROR(C9/C6,0) -> 0.90801481 | D10: =IFERROR(D9/D6,0) -> 0.91898417 | E10: =IFERROR(E9/E6,0) -> 0.91154681 | F10: =IFERROR(F9/F6,0) -> 0.90752356 | G10: =IFERROR(G9/G6,0) -> 0.91080992 | H10: =IFERROR(H9/H6,0) -> 0.91590812 | I10: =IFERROR(I9/I6,0) -> 0.87184779
B12: Gross Profit | C12: =IFERROR(C6-C9,0) -> 2287.69 | D12: =IFERROR(D6-D9,0) -> 1955.97 | E12: =IFERROR(E6-E9,0) -> 2739.95 | F12: =IFERROR(F6-F9,0) -> 3961.65 | G12: =IFERROR(G6-G9,0) -> 4529.86 | H12: =IFERROR(H6-H9,0) -> 4991.53 | I12: =IFERROR(I6-I9,0) -> 8819.53 | J12: =IFERROR(J6-J9,0) -> -65868.68
B13: Gross Margin | C13: =IFERROR(C12/C6,0) -> 0.091985187 | D13: =IFERROR(D12/D6,0) -> 0.081015828 | E13: =IFERROR(E12/E6,0) -> 0.088453193 | F13: =IFERROR(F12/F6,0) -> 0.09247644 | G13: =IFERROR(G12/G6,0) -> 0.089190084 | H13: =IFERROR(H12/H6,0) -> 0.08409188 | I13: =IFERROR(I12/I6,0) -> 0.12815221 | J13: =IFERROR(J12/J6,0) -> 0
B15: Selling & General Expenses | C15: =IFERROR(SUM('Data Sheet'!E23:E24),0) -> 347.62 | D15: =IFERROR(SUM('Data Sheet'!F23:F24),0) -> 385.34 | E15: =IFERROR(SUM('Data Sheet'!G23:G24),0) -> 445.46 | F15: =IFERROR(SUM('Data Sheet'!H23:H24),0) -> 637.5 | G15: =IFERROR(SUM('Data Sheet'!I23:I24),0) -> 800.81 | H15: =IFERROR(SUM('Data Sheet'!J23:J24),0) -> 944.77 | I15: =IFERROR(SUM('Data Sheet'!K23:K24),0) -> 3632.94
B16: S&G Exp. | C16: =C15/C6 -> 0.013977371 | D16: =D15/D6 -> 0.015960694 | E16: =E15/E6 -> 0.014380686 | F16: =F15/F6 -> 0.014881105 | G16: =G15/G6 -> 0.015767443 | H16: =H15/H6 -> 0.01591646 | I16: =I15/I6 -> 0.052788447 | J16: =J15/J6 -> #DIV/0!
B18: EBITDA | C18: =IFERROR(C12-C15,0) -> 1940.07 | D18: =IFERROR(D12-D15,0) -> 1570.63 | E18: =IFERROR(E12-E15,0) -> 2294.49 | F18: =IFERROR(F12-F15,0) -> 3324.15 | G18: =IFERROR(G12-G15,0) -> 3729.05 | H18: =IFERROR(H12-H15,0) -> 4046.76 | I18: =IFERROR(I12-I15,0) -> 5186.59 | J18: =IFERROR(SUM('Data Sheet'!H50:K50),0) -> 5386.89
B19: EBITDA Margin | C19: =C18/C6 -> 0.078007817 | D19: =D18/D6 -> 0.065055134 | E19: =E18/E6 -> 0.074072508 | F19: =F18/F6 -> 0.077595335 | G19: =G18/G6 -> 0.07342264 | H19: =H18/H6 -> 0.06817542 | I19: =I18/I6 -> 0.075363764 | J19: =J18/J6 -> #DIV/0!
B21: Interest | C21: =IFERROR('Data Sheet'!E27,0) -> 69.12 | D21: =IFERROR('Data Sheet'!F27,0) -> 41.65 | E21: =IFERROR('Data Sheet'!G27,0) -> 53.79 | F21: =IFERROR('Data Sheet'!H27,0) -> 67.41 | G21: =IFERROR('Data Sheet'!I27,0) -> 58.13 | H21: =IFERROR('Data Sheet'!J27,0) -> 69.45 | I21: =IFERROR('Data Sheet'!K27,0) -> 142.05 | J21: =IFERROR(SUM('Data Sheet'!H46:K46),0) -> 167.03
B22: Interest % Sales | C22: =IFERROR(C21/C6,0) -> 0.0027792298 | D22: =IFERROR(D21/D6,0) -> 0.0017251334 | E22: =IFERROR(E21/E6,0) -> 0.0017364905 | F22: =IFERROR(F21/F6,0) -> 0.0015735456 | G22: =IFERROR(G21/G6,0) -> 0.001144543 | H22: =IFERROR(H21/H6,0) -> 0.0011700182 | I22: =IFERROR(I21/I6,0) -> 0.002064058 | J22: =IFERROR(J21/J6,0) -> 0
B24: Depreciation | C24: =IFERROR('Data Sheet'!E26,0) -> 374.41 | D24: =IFERROR('Data Sheet'!F26,0) -> 414.16 | E24: =IFERROR('Data Sheet'!G26,0) -> 498.08 | F24: =IFERROR('Data Sheet'!H26,0) -> 638.87 | G24: =IFERROR('Data Sheet'!I26,0) -> 730.76 | H24: =IFERROR('Data Sheet'!J26,0) -> 869.52 | I24: =IFERROR('Data Sheet'!K26,0) -> 1037.02 | J24: =IFERROR(SUM('Data Sheet'!H45:K45),0) -> 1093.02
B25: Depreciation % Sales | C25: =IFERROR(C24/C6,0) -> 0.015054563 | D25: =IFERROR(D24/D6,0) -> 0.017154412 | E25: =IFERROR(E24/E6,0) -> 0.016079405 | F25: =IFERROR(F24/F6,0) -> 0.014913085 | G25: =IFERROR(G24/G6,0) -> 0.014388203 | H25: =IFERROR(H24/H6,0) -> 0.014648729 | I25: =IFERROR(I24/I6,0) -> 0.015068423 | J25: =IFERROR(J24/J6,0) -> 0
B27: EBT | C27: =IFERROR(C18-SUM(C21,C24),0) -> 1496.54 | D27: =IFERROR(D18-SUM(D21,D24),0) -> 1114.82 | E27: =IFERROR(E18-SUM(E21,E24),0) -> 1742.62 | F27: =IFERROR(F18-SUM(F21,F24),0) -> 2617.87 | G27: =IFERROR(G18-SUM(G21,G24),0) -> 2940.16 | H27: =IFERROR(H18-SUM(H21,H24),0) -> 3107.79 | I27: =IFERROR(I18-SUM(I21,I24),0) -> 4007.52 | J27: =IFERROR(J18-SUM(J21,J24),0) -> 4126.84
B28: EBT % Sales | C28: =IFERROR(C27/C6,0) -> 0.060174024 | D28: =IFERROR(D27/D6,0) -> 0.046175588 | E28: =IFERROR(E27/E6,0) -> 0.056256612 | F28: =IFERROR(F27/F6,0) -> 0.061108704 | G28: =IFERROR(G27/G6,0) -> 0.057889894 | H28: =IFERROR(H27/H6,0) -> 0.052356673 | I28: =IFERROR(I27/I6,0) -> 0.058231283 | J28: =IFERROR(J27/J6,0) -> 0
B30: Tax | C30: =IFERROR('Data Sheet'!E30-'Data Sheet'!E28,0) -> -443.69 | D30: =IFERROR('Data Sheet'!F30-'Data Sheet'!F28,0) -> -383.96 | E30: =IFERROR('Data Sheet'!G30-'Data Sheet'!G28,0) -> -571.57 | F30: =IFERROR('Data Sheet'!H30-'Data Sheet'!H28,0) -> -681.58 | G30: =IFERROR('Data Sheet'!I30-'Data Sheet'!I28,0) -> -925.16 | H30: =IFERROR('Data Sheet'!J30-'Data Sheet'!J28,0) -> -964.65 | I30: =IFERROR('Data Sheet'!K30-'Data Sheet'!K28,0) -> -1111.13 | J30: =IFERROR('Data Sheet'!L30-'Data Sheet'!L28,0) -> 0
B31: Effective Tax Rate | C31: =IFERROR(C30/C27,0) -> -0.29647721 | D31: =IFERROR(D30/D27,0) -> -0.34441434 | E31: =IFERROR(E30/E27,0) -> -0.32799463 | F31: =IFERROR(F30/F27,0) -> -0.2603567 | G31: =IFERROR(G30/G27,0) -> -0.31466315 | H31: =IFERROR(H30/H27,0) -> -0.31039742 | I31: =IFERROR(I30/I27,0) -> -0.27726125 | J31: =IFERROR(J30/J27,0) -> 0
B33: Net Profit | C33: =IFERROR(C27-C30,0) -> 1940.23 | D33: =IFERROR(D27-D30,0) -> 1498.78 | E33: =IFERROR(E27-E30,0) -> 2314.19 | F33: =IFERROR(F27-F30,0) -> 3299.45 | G33: =IFERROR(G27-G30,0) -> 3865.32 | H33: =IFERROR(H27-H30,0) -> 4072.44 | I33: =IFERROR(I27-I30,0) -> 5118.65 | J33: =IFERROR(J27-J30,0) -> 4126.84
B34: Net Margin | C34: =IFERROR(C33/C6,0) -> 0.07801425 | D34: =IFERROR(D33/D6,0) -> 0.062079123 | E34: =IFERROR(E33/E6,0) -> 0.074708478 | F34: =IFERROR(F33/F6,0) -> 0.077018765 | G34: =IFERROR(G33/G6,0) -> 0.076105711 | H34: =IFERROR(H33/H6,0) -> 0.068608049 | I34: =IFERROR(I33/I6,0) -> 0.074376561 | J34: =IFERROR(J33/J6,0) -> 0
B36: No. of Equity Shares | C36: =IFERROR('Data Sheet'!E93,0) -> 64.78 | D36: =IFERROR('Data Sheet'!F93,0) -> 64.78 | E36: =IFERROR('Data Sheet'!G93,0) -> 64.78 | F36: =IFERROR('Data Sheet'!H93,0) -> 64.83 | G36: =IFERROR('Data Sheet'!I93,0) -> 65.07 | H36: =IFERROR('Data Sheet'!J93,0) -> 65.07 | I36: =IFERROR('Data Sheet'!K93,0) -> 65.2
B38: EPS | C38: =IFERROR(C33/C36,0) -> 29.951065 | D38: =IFERROR(D33/D36,0) -> 23.136462 | E38: =IFERROR(E33/E36,0) -> 35.723835 | F38: =IFERROR(F33/F36,0) -> 50.893876 | G38: =IFERROR(G33/G36,0) -> 59.40249 | H38: =IFERROR(H33/H36,0) -> 62.585523 | I38: =IFERROR(I33/I36,0) -> 78.506902
B39: EPS Growth | D39: =IFERROR(D38/C38-1,0) -> -0.22752457 | E39: =IFERROR(E38/D38-1,0) -> 0.54404916 | F39: =IFERROR(F38/E38-1,0) -> 0.42464763 | G39: =IFERROR(G38/F38-1,0) -> 0.16718344 | H39: =IFERROR(H38/G38-1,0) -> 0.053584179 | I39: =IFERROR(I38/H38-1,0) -> 0.25439395
B41: Dividend per share | C41: 0 | D41: 0 | E41: 0 | F41: 0 | G41: 0 | H41: 0 | I41: 0
B42: Dividend payout ratio | C42: =IFERROR(C41/C38,0) -> 0 | D42: =IFERROR(D41/D38,0) -> 0 | E42: =IFERROR(E41/E38,0) -> 0 | F42: =IFERROR(F41/F38,0) -> 0 | G42: =IFERROR(G41/G38,0) -> 0 | H42: =IFERROR(H41/H38,0) -> 0 | I42: =IFERROR(I41/I38,0) -> 0
B44: Retained Earnings | C44: =IFERROR(IF(C38>C41,1-C42,0),0) -> 1 | D44: =IFERROR(IF(D38>D41,1-D42,0),0) -> 1 | E44: =IFERROR(IF(E38>E41,1-E42,0),0) -> 1 | F44: =IFERROR(IF(F38>F41,1-F42,0),0) -> 1 | G44: =IFERROR(IF(G38>G41,1-G42,0),0) -> 1 | H44: =IFERROR(IF(H38>H41,1-H42,0),0) -> 1 | I44: =IFERROR(IF(I38>I41,1-I42,0),0) -> 1
A46: # | B46: Balance Sheet
B47: Equity Share Capital | C47: =IFERROR('Data Sheet'!E57,0) -> 647.77 | D47: =IFERROR('Data Sheet'!F57,0) -> 647.77 | E47: =IFERROR('Data Sheet'!G57,0) -> 647.77 | F47: =IFERROR('Data Sheet'!H57,0) -> 648.26 | G47: =IFERROR('Data Sheet'!I57,0) -> 650.73 | H47: =IFERROR('Data Sheet'!J57,0) -> 650.73 | I47: =IFERROR('Data Sheet'!K57,0) -> 651.96
B48: Reserves | C48: =IFERROR('Data Sheet'!E58,0) -> 10431.97 | D48: =IFERROR('Data Sheet'!F58,0) -> 11535.94 | E48: =IFERROR('Data Sheet'!G58,0) -> 13029.87 | F48: =IFERROR('Data Sheet'!H58,0) -> 15430.44 | G48: =IFERROR('Data Sheet'!I58,0) -> 18047.09 | H48: =IFERROR('Data Sheet'!J58,0) -> 20777.02 | I48: =IFERROR('Data Sheet'!K58,0) -> 23812.08
B49: Borrowings | C49: =IFERROR('Data Sheet'!E59,0) -> 333.19 | D49: =IFERROR('Data Sheet'!F59,0) -> 392.71 | E49: =IFERROR('Data Sheet'!G59,0) -> 646.94 | F49: =IFERROR('Data Sheet'!H59,0) -> 642.98 | G49: =IFERROR('Data Sheet'!I59,0) -> 592.16 | H49: =IFERROR('Data Sheet'!J59,0) -> 819.62 | I49: =IFERROR('Data Sheet'!K59,0) -> 2424.99
B50: Other Liabilities | C50: =IFERROR('Data Sheet'!E60,0) -> 663.23 | D50: =IFERROR('Data Sheet'!F60,0) -> 1078.63 | E50: =IFERROR('Data Sheet'!G60,0) -> 1146.4 | F50: =IFERROR('Data Sheet'!H60,0) -> 1382.84 | G50: =IFERROR('Data Sheet'!I60,0) -> 1882.5 | H50: =IFERROR('Data Sheet'!J60,0) -> 2065.41 | I50: =IFERROR('Data Sheet'!K60,0) -> 2635.23
B51: Total Liabilities | C51: =IFERROR(SUM(C47:C50),0) -> 12076.16 | D51: =IFERROR(SUM(D47:D50),0) -> 13655.05 | E51: =IFERROR(SUM(E47:E50),0) -> 15470.98 | F51: =IFERROR(SUM(F47:F50),0) -> 18104.52 | G51: =IFERROR(SUM(G47:G50),0) -> 21172.48 | H51: =IFERROR(SUM(H47:H50),0) -> 24312.78 | I51: =IFERROR(SUM(I47:I50),0) -> 29524.26
B53: Fixed Assets Net Block | C53: =IFERROR('Data Sheet'!E62,0) -> 5948.03 | D53: =IFERROR('Data Sheet'!F62,0) -> 7008.8 | E53: =IFERROR('Data Sheet'!G62,0) -> 9260.02 | F53: =IFERROR('Data Sheet'!H62,0) -> 11340.48 | G53: =IFERROR('Data Sheet'!I62,0) -> 13415 | H53: =IFERROR('Data Sheet'!J62,0) -> 16206.46 | I53: =IFERROR('Data Sheet'!K62,0) -> 20090.31
B54: Capital Work in Progress | C54: =IFERROR('Data Sheet'!E63,0) -> 364.4 | D54: =IFERROR('Data Sheet'!F63,0) -> 1019.59 | E54: =IFERROR('Data Sheet'!G63,0) -> 1129.34 | F54: =IFERROR('Data Sheet'!H63,0) -> 829.16 | G54: =IFERROR('Data Sheet'!I63,0) -> 935.22 | H54: =IFERROR('Data Sheet'!J63,0) -> 1099.35 | I54: =IFERROR('Data Sheet'!K63,0) -> 1299.96
B55: Investments | C55: =IFERROR('Data Sheet'!E64,0) -> 14.68 | D55: =IFERROR('Data Sheet'!F64,0) -> 2.95 | E55: =IFERROR('Data Sheet'!G64,0) -> 5.94 | F55: =IFERROR('Data Sheet'!H64,0) -> 202.2 | G55: =IFERROR('Data Sheet'!I64,0) -> 106.67 | H55: =IFERROR('Data Sheet'!J64,0) -> 3.26 | I55: =IFERROR('Data Sheet'!K64,0) -> 4.01
B56: Other Assets | C56: =IFERROR('Data Sheet'!E65-SUM('Data Sheet'!E67:E69),0) -> 3674.22 | D56: =IFERROR('Data Sheet'!F65-SUM('Data Sheet'!F67:F69),0) -> 1886.27 | E56: =IFERROR('Data Sheet'!G65-SUM('Data Sheet'!G67:G69),0) -> 1967.55 | F56: =IFERROR('Data Sheet'!H65-SUM('Data Sheet'!H67:H69),0) -> 1018.71 | G56: =IFERROR('Data Sheet'!I65-SUM('Data Sheet'!I67:I69),0) -> 1983.73 | H56: =IFERROR('Data Sheet'!J65-SUM('Data Sheet'!J67:J69),0) -> 1447.35 | I56: =IFERROR('Data Sheet'!K65-SUM('Data Sheet'!K67:K69),0) -> 1776.22
B57: Total Non Current Assets | C57: =IFERROR(SUM(C53:C56),0) -> 10001.33 | D57: =IFERROR(SUM(D53:D56),0) -> 9917.61 | E57: =IFERROR(SUM(E53:E56),0) -> 12362.85 | F57: =IFERROR(SUM(F53:F56),0) -> 13390.55 | G57: =IFERROR(SUM(G53:G56),0) -> 16440.62 | H57: =IFERROR(SUM(H53:H56),0) -> 18756.42 | I57: =IFERROR(SUM(I53:I56),0) -> 23170.5
...

Sheet Common Size Statement
A2: # | B2: ="Common Size P&L Statement-"&'Data Sheet'!B1 -> Common Size P&L Statement-AVENUE SUPERMARTS LTD
B4: Particular | C4: ='Data Sheet'!E16 -> 43921 | D4: ='Data Sheet'!F16 -> 44286 | E4: ='Data Sheet'!G16 -> 44651 | F4: ='Data Sheet'!H16 -> 45016 | G4: ='Data Sheet'!I16 -> 45382 | H4: ='Data Sheet'!J16 -> 45747 | I4: ='Data Sheet'!K16 -> 46112
B6: Sales | C6: ='Data Sheet'!E17/'Data Sheet'!E$17 -> 1 | D6: ='Data Sheet'!F17/'Data Sheet'!F$17 -> 1 | E6: ='Data Sheet'!G17/'Data Sheet'!G$17 -> 1 | F6: ='Data Sheet'!H17/'Data Sheet'!H$17 -> 1 | G6: ='Data Sheet'!I17/'Data Sheet'!I$17 -> 1 | H6: ='Data Sheet'!J17/'Data Sheet'!J$17 -> 1 | I6: ='Data Sheet'!K17/'Data Sheet'!K$17 -> 1
B7: Raw Material Cost | C7: ='Data Sheet'!E18/'Data Sheet'!E$17 -> 0.86214345 | D7: ='Data Sheet'!F18/'Data Sheet'!F$17 -> 0.86383251 | E7: ='Data Sheet'!G18/'Data Sheet'!G$17 -> 0.868141 | F7: ='Data Sheet'!H18/'Data Sheet'!H$17 -> 0.86099787 | G7: ='Data Sheet'!I18/'Data Sheet'!I$17 -> 0.86551137 | H7: ='Data Sheet'!J18/'Data Sheet'!J$17 -> 0.87045919 | I7: ='Data Sheet'!K18/'Data Sheet'!K$17 -> 0.8618912
B8: Change in Inventory | C8: ='Data Sheet'!E19/'Data Sheet'!E$17 -> 0.013620719 | D8: ='Data Sheet'!F19/'Data Sheet'!F$17 -> 0.01246238 | E8: ='Data Sheet'!G19/'Data Sheet'!G$17 -> 0.015959959 | F8: ='Data Sheet'!H19/'Data Sheet'!H$17 -> 0.011690596 | G8: ='Data Sheet'!I19/'Data Sheet'!I$17 -> 0.013463 | H8: ='Data Sheet'!J19/'Data Sheet'!J$17 -> 0.018819014 | I8: ='Data Sheet'!K19/'Data Sheet'!K$17 -> 0.012441889
B9: Power and Fuel | C9: ='Data Sheet'!E20/'Data Sheet'!E$17 -> 0.0075688977 | D9: ='Data Sheet'!F20/'Data Sheet'!F$17 -> 0.007215324 | E9: ='Data Sheet'!G20/'Data Sheet'!G$17 -> 0.0067102979 | F9: ='Data Sheet'!H20/'Data Sheet'!H$17 -> 0.0073441464 | G9: ='Data Sheet'!I20/'Data Sheet'!I$17 -> 0.0074148194 | H9: ='Data Sheet'!J20/'Data Sheet'!J$17 -> 0.007543206 | I9: ='Data Sheet'!K20/'Data Sheet'!K$17 -> 0
B10: Other Mfr. Exp | C10: ='Data Sheet'!E21/'Data Sheet'!E$17 -> 0.025973253 | D10: ='Data Sheet'!F21/'Data Sheet'!F$17 -> 0.030916959 | E10: ='Data Sheet'!G21/'Data Sheet'!G$17 -> 0.026015075 | F10: ='Data Sheet'!H21/'Data Sheet'!H$17 -> 0.02606376 | G10: ='Data Sheet'!I21/'Data Sheet'!I$17 -> 0.026057501 | H10: ='Data Sheet'!J21/'Data Sheet'!J$17 -> 0.029513267 | I10: ='Data Sheet'!K21/'Data Sheet'!K$17 -> 0
B11: Employee Cost | C11: ='Data Sheet'!E22/'Data Sheet'!E$17 -> 0.018381034 | D11: ='Data Sheet'!F22/'Data Sheet'!F$17 -> 0.02226644 | E11: ='Data Sheet'!G22/'Data Sheet'!G$17 -> 0.019930095 | F11: ='Data Sheet'!H22/'Data Sheet'!H$17 -> 0.017464232 | G11: ='Data Sheet'!I22/'Data Sheet'!I$17 -> 0.017874403 | H11: ='Data Sheet'!J22/'Data Sheet'!J$17 -> 0.019668267 | I11: ='Data Sheet'!K22/'Data Sheet'!K$17 -> 0.02239848
B12: Selling and admin | C12: ='Data Sheet'!E23/'Data Sheet'!E$17 -> 0.0026698619 | D12: ='Data Sheet'!F23/'Data Sheet'!F$17 -> 0.0045019148 | E12: ='Data Sheet'!G23/'Data Sheet'!G$17 -> 0.004629673 | F12: ='Data Sheet'!H23/'Data Sheet'!H$17 -> 0.0049496307 | G12: ='Data Sheet'!I23/'Data Sheet'!I$17 -> 0.0054033535 | H12: ='Data Sheet'!J23/'Data Sheet'!J$17 -> 0.0052643239 | I12: ='Data Sheet'!K23/'Data Sheet'!K$17 -> 0
B13: Other Expenses | C13: ='Data Sheet'!E24/'Data Sheet'!E$17 -> 0.011307509 | D13: ='Data Sheet'!F24/'Data Sheet'!F$17 -> 0.011458779 | E13: ='Data Sheet'!G24/'Data Sheet'!G$17 -> 0.0097510126 | F13: ='Data Sheet'!H24/'Data Sheet'!H$17 -> 0.0099314746 | G13: ='Data Sheet'!I24/'Data Sheet'!I$17 -> 0.01036409 | H13: ='Data Sheet'!J24/'Data Sheet'!J$17 -> 0.010652136 | I13: ='Data Sheet'!K24/'Data Sheet'!K$17 -> 0.052788447
B14: Other Income | C14: ='Data Sheet'!E25/'Data Sheet'!E$17 -> 0.0024121237 | D14: ='Data Sheet'!F25/'Data Sheet'!F$17 -> 0.0080532459 | E14: ='Data Sheet'!G25/'Data Sheet'!G$17 -> 0.0036686147 | F14: ='Data Sheet'!H25/'Data Sheet'!H$17 -> 0.0029785553 | G14: ='Data Sheet'!I25/'Data Sheet'!I$17 -> 0.0028466889 | H14: ='Data Sheet'!J25/'Data Sheet'!J$17 -> 0.0019732791 | I14: ='Data Sheet'!K25/'Data Sheet'!K$17 -> 0.0010767103
B15: Depreciation | C15: ='Data Sheet'!E26/'Data Sheet'!E$17 -> 0.015054563 | D15: ='Data Sheet'!F26/'Data Sheet'!F$17 -> 0.017154412 | E15: ='Data Sheet'!G26/'Data Sheet'!G$17 -> 0.016079405 | F15: ='Data Sheet'!H26/'Data Sheet'!H$17 -> 0.014913085 | G15: ='Data Sheet'!I26/'Data Sheet'!I$17 -> 0.014388203 | H15: ='Data Sheet'!J26/'Data Sheet'!J$17 -> 0.014648729 | I15: ='Data Sheet'!K26/'Data Sheet'!K$17 -> 0.015068423
B16: Interest | C16: ='Data Sheet'!E27/'Data Sheet'!E$17 -> 0.0027792298 | D16: ='Data Sheet'!F27/'Data Sheet'!F$17 -> 0.0017251334 | E16: ='Data Sheet'!G27/'Data Sheet'!G$17 -> 0.0017364905 | F16: ='Data Sheet'!H27/'Data Sheet'!H$17 -> 0.0015735456 | G16: ='Data Sheet'!I27/'Data Sheet'!I$17 -> 0.001144543 | H16: ='Data Sheet'!J27/'Data Sheet'!J$17 -> 0.0011700182 | I16: ='Data Sheet'!K27/'Data Sheet'!K$17 -> 0.002064058
B17: Profit before tax | C17: ='Data Sheet'!E28/'Data Sheet'!E$17 -> 0.070155045 | D17: ='Data Sheet'!F28/'Data Sheet'!F$17 -> 0.061444158 | E17: ='Data Sheet'!G28/'Data Sheet'!G$17 -> 0.066635525 | F17: ='Data Sheet'!H28/'Data Sheet'!H$17 -> 0.071431406 | G17: ='Data Sheet'!I28/'Data Sheet'!I$17 -> 0.068151403 | H17: ='Data Sheet'!J28/'Data Sheet'!J$17 -> 0.061873158 | I17: ='Data Sheet'!K28/'Data Sheet'!K$17 -> 0.059307993
... B20: Dividend Amount | C20: ='Data Sheet'!E31/'Data Sheet'!E$17 -> 0 | D20: ='Data Sheet'!F31/'Data Sheet'!F$17 -> 0 | E20: ='Data Sheet'!G31/'Data Sheet'!G$17 -> 0 | F20: ='Data Sheet'!H31/'Data Sheet'!H$17 -> 0 | G20: ='Data Sheet'!I31/'Data Sheet'!I$17 -> 0 | H20: ='Data Sheet'!J31/'Data Sheet'!J$17 -> 0 | I20: ='Data Sheet'!K31/'Data Sheet'!K$17 -> 0
B21: EBITDA | C21: ='Historicial Financials'!C18/'Historicial Financials'!C$6 -> 0.078007817 | D21: ='Historicial Financials'!D18/'Historicial Financials'!D$6 -> 0.065055134 | E21: ='Historicial Financials'!E18/'Historicial Financials'!E$6 -> 0.074072508 | F21: ='Historicial Financials'!F18/'Historicial Financials'!F$6 -> 0.077595335 | G21: ='Historicial Financials'!G18/'Historicial Financials'!G$6 -> 0.07342264 | H21: ='Historicial Financials'!H18/'Historicial Financials'!H$6 -> 0.06817542 | I21: ='Historicial Financials'!I18/'Historicial Financials'!I$6 -> 0.075363764
A23: # | B23: ="Common Size Balance sheet Statement-"&'Data Sheet'!B1 -> Common Size Balance sheet Statement-AVENUE SUPERMARTS LTD
B25: Particular | C25: ='Data Sheet'!E16 -> 43921 | D25: ='Data Sheet'!F16 -> 44286 | E25: ='Data Sheet'!G16 -> 44651 | F25: ='Data Sheet'!H16 -> 45016 | G25: ='Data Sheet'!I16 -> 45382 | H25: ='Data Sheet'!J16 -> 45747 | I25: ='Data Sheet'!K16 -> 46112
B27: Total Liabilities | C27: ='Data Sheet'!E61/'Data Sheet'!E$61 -> 1 | D27: ='Data Sheet'!F61/'Data Sheet'!F$61 -> 1 | E27: ='Data Sheet'!G61/'Data Sheet'!G$61 -> 1 | F27: ='Data Sheet'!H61/'Data Sheet'!H$61 -> 1 | G27: ='Data Sheet'!I61/'Data Sheet'!I$61 -> 1 | H27: ='Data Sheet'!J61/'Data Sheet'!J$61 -> 1 | I27: ='Data Sheet'!K61/'Data Sheet'!K$61 -> 1
B28: Equity Share Capital | C28: ='Data Sheet'!E57/'Data Sheet'!E$61 -> 0.053640396 | D28: ='Data Sheet'!F57/'Data Sheet'!F$61 -> 0.047438127 | E28: ='Data Sheet'!G57/'Data Sheet'!G$61 -> 0.041870004 | F28: ='Data Sheet'!H57/'Data Sheet'!H$61 -> 0.035806528 | G28: ='Data Sheet'!I57/'Data Sheet'!I$61 -> 0.030734708 | H28: ='Data Sheet'!J57/'Data Sheet'!J$61 -> 0.026764936 | I28: ='Data Sheet'!K57/'Data Sheet'!K$61 -> 0.022082179
B29: Reserves | C29: ='Data Sheet'!E58/'Data Sheet'!E$61 -> 0.86384828 | D29: ='Data Sheet'!F58/'Data Sheet'!F$61 -> 0.84481126 | E29: ='Data Sheet'!G58/'Data Sheet'!G$61 -> 0.84221362 | F29: ='Data Sheet'!H58/'Data Sheet'!H$61 -> 0.85229766 | G29: ='Data Sheet'!I58/'Data Sheet'!I$61 -> 0.85238432 | H29: ='Data Sheet'!J58/'Data Sheet'!J$61 -> 0.85457196 | I29: ='Data Sheet'!K58/'Data Sheet'!K$61 -> 0.80652589
B30: Borrowings | C30: ='Data Sheet'!E59/'Data Sheet'!E$61 -> 0.027590724 | D30: ='Data Sheet'!F59/'Data Sheet'!F$61 -> 0.028759323 | E30: ='Data Sheet'!G59/'Data Sheet'!G$61 -> 0.041816356 | F30: ='Data Sheet'!H59/'Data Sheet'!H$61 -> 0.035514888 | G30: ='Data Sheet'!I59/'Data Sheet'!I$61 -> 0.027968382 | H30: ='Data Sheet'!J59/'Data Sheet'!J$61 -> 0.033711488 | I30: ='Data Sheet'!K59/'Data Sheet'!K$61 -> 0.082135505
B31: Other Liabilities | C31: ='Data Sheet'!E60/'Data Sheet'!E$61 -> 0.054920604 | D31: ='Data Sheet'!F60/'Data Sheet'!F$61 -> 0.078991289 | E31: ='Data Sheet'!G60/'Data Sheet'!G$61 -> 0.074100025 | F31: ='Data Sheet'!H60/'Data Sheet'!H$61 -> 0.076380926 | G31: ='Data Sheet'!I60/'Data Sheet'!I$61 -> 0.088912588 | H31: ='Data Sheet'!J60/'Data Sheet'!J$61 -> 0.084951618 | I31: ='Data Sheet'!K60/'Data Sheet'!K$61 -> 0.089256428
B33: Total Assets | C33: ='Data Sheet'!E61/'Data Sheet'!E$61 -> 1 | D33: ='Data Sheet'!F61/'Data Sheet'!F$61 -> 1 | E33: ='Data Sheet'!G61/'Data Sheet'!G$61 -> 1 | F33: ='Data Sheet'!H61/'Data Sheet'!H$61 -> 1 | G33: ='Data Sheet'!I61/'Data Sheet'!I$61 -> 1 | H33: ='Data Sheet'!J61/'Data Sheet'!J$61 -> 1 | I33: ='Data Sheet'!K61/'Data Sheet'!K$61 -> 1
B34: Fixed Assets Net Block | C34: ='Data Sheet'!E62/'Data Sheet'!E$61 -> 0.49254316 | D34: ='Data Sheet'!F62/'Data Sheet'!F$61 -> 0.51327531 | E34: ='Data Sheet'!G62/'Data Sheet'!G$61 -> 0.59854127 | F34: ='Data Sheet'!H62/'Data Sheet'!H$61 -> 0.62638943 | G34: ='Data Sheet'!I62/'Data Sheet'!I$61 -> 0.63360551 | H34: ='Data Sheet'!J62/'Data Sheet'!J$61 -> 0.66658194 | I34: ='Data Sheet'!K62/'Data Sheet'!K$61 -> 0.68046786
B35: Capital Work in Progress | C35: ='Data Sheet'!E63/'Data Sheet'!E$61 -> 0.030175155 | D35: ='Data Sheet'!F63/'Data Sheet'!F$61 -> 0.074667614 | E35: ='Data Sheet'!G63/'Data Sheet'!G$61 -> 0.072997315 | F35: ='Data Sheet'!H63/'Data Sheet'!H$61 -> 0.045798508 | G35: ='Data Sheet'!I63/'Data Sheet'!I$61 -> 0.044171491 | H35: ='Data Sheet'!J63/'Data Sheet'!J$61 -> 0.04521696 | I35: ='Data Sheet'!K63/'Data Sheet'!K$61 -> 0.044030231
B36: Investments | C36: ='Data Sheet'!E64/'Data Sheet'!E$61 -> 0.0012156182 | D36: ='Data Sheet'!F64/'Data Sheet'!F$61 -> 0.00021603729 | E36: ='Data Sheet'!G64/'Data Sheet'!G$61 -> 0.00038394465 | F36: ='Data Sheet'!H64/'Data Sheet'!H$61 -> 0.011168482 | G36: ='Data Sheet'!I64/'Data Sheet'!I$61 -> 0.0050381439 | H36: ='Data Sheet'!J64/'Data Sheet'!J$61 -> 0.00013408586 | I36: ='Data Sheet'!K64/'Data Sheet'!K$61 -> 0.00013582051
B37: Other Assets | C37: ='Data Sheet'!E65/'Data Sheet'!E$61 -> 0.47606607 | D37: ='Data Sheet'!F65/'Data Sheet'!F$61 -> 0.41184104 | E37: ='Data Sheet'!G65/'Data Sheet'!G$61 -> 0.32807747 | F37: ='Data Sheet'!H65/'Data Sheet'!H$61 -> 0.31664358 | G37: ='Data Sheet'!I65/'Data Sheet'!I$61 -> 0.31718486 | H37: ='Data Sheet'!J65/'Data Sheet'!J$61 -> 0.28806702 | I37: ='Data Sheet'!K65/'Data Sheet'!K$61 -> 0.27536609
B38: Receivables | C38: ='Data Sheet'!E67/'Data Sheet'!E$61 -> 0.0016188921 | D38: ='Data Sheet'!F67/'Data Sheet'!F$61 -> 0.0031914933 | E38: ='Data Sheet'!G67/'Data Sheet'!G$61 -> 0.0043235787 | F38: ='Data Sheet'!H67/'Data Sheet'!H$61 -> 0.0034333967 | G38: ='Data Sheet'!I67/'Data Sheet'!I$61 -> 0.0078578419 | H38: ='Data Sheet'!J67/'Data Sheet'!J$61 -> 0.0063254799 | I38: ='Data Sheet'!K67/'Data Sheet'!K$61 -> 0.0050582131
B39: Inventory | C39: ='Data Sheet'!E68/'Data Sheet'!E$61 -> 0.16125987 | D39: ='Data Sheet'!F68/'Data Sheet'!F$61 -> 0.16464824 | E39: ='Data Sheet'!G68/'Data Sheet'!G$61 -> 0.17727772 | F39: ='Data Sheet'!H68/'Data Sheet'!H$61 -> 0.17915305 | G39: ='Data Sheet'!I68/'Data Sheet'!I$61 -> 0.18549126 | H39: ='Data Sheet'!J68/'Data Sheet'!J$61 -> 0.20747812 | I39: ='Data Sheet'!K68/'Data Sheet'!K$61 -> 0.19985734
B40: Cash & Bank | C40: ='Data Sheet'!E69/'Data Sheet'!E$61 -> 0.0089333033 | D40: ='Data Sheet'!F69/'Data Sheet'!F$61 -> 0.10586413 | E40: ='Data Sheet'!G69/'Data Sheet'!G$61 -> 0.019299359 | F40: ='Data Sheet'!H69/'Data Sheet'!H$61 -> 0.077788862 | G40: ='Data Sheet'!I69/'Data Sheet'!I$61 -> 0.030141958 | H40: ='Data Sheet'!J69/'Data Sheet'!J$61 -> 0.014732992 | I40: ='Data Sheet'!K69/'Data Sheet'!K$61 -> 0.010289166

Sheet Ratio Analysis
B2: Historical Financial Statement-SWIGGY LTD
B4: Years | C4: ='Historicial Financials'!C3 -> 43921 | D4: ='Historicial Financials'!D3 -> 44286 | E4: ='Historicial Financials'!E3 -> 44651 | F4: ='Historicial Financials'!F3 -> 45016 | G4: ='Historicial Financials'!G3 -> 45382 | H4: ='Historicial Financials'!H3 -> 45747 | I4: ='Historicial Financials'!I3 -> 46112 | J4: Trend | K4: Mean | L4: Median
B6: SalesGrowth | D6: =IFERROR('Historicial Financials'!D7,0) -> -0.029237401 | E6: =IFERROR('Historicial Financials'!E7,0) -> 0.28302999 | F6: =IFERROR('Historicial Financials'!F7,0) -> 0.38297994 | G6: =IFERROR('Historicial Financials'!G7,0) -> 0.1855591 | H6: =IFERROR('Historicial Financials'!H7,0) -> 0.16872253 | I6: =IFERROR('Historicial Financials'!I7,0) -> 0.15941713 | K6: =IFERROR(AVERAGE(D6:I6),0) -> 0.19174521 | L6: =IFERROR(MEDIAN(D6:I6),0) -> 0.17714081
B7: EBITDA Growth | D7: =IFERROR('Historicial Financials'!D18/'Historicial Financials'!C18-1,0) -> -0.19042612 | E7: =IFERROR('Historicial Financials'!E18/'Historicial Financials'!D18-1,0) -> 0.46087239 | F7: =IFERROR('Historicial Financials'!F18/'Historicial Financials'!E18-1,0) -> 0.44875332 | G7: =IFERROR('Historicial Financials'!G18/'Historicial Financials'!F18-1,0) -> 0.12180557 | H7: =IFERROR('Historicial Financials'!H18/'Historicial Financials'!G18-1,0) -> 0.085198643 | I7: =IFERROR('Historicial Financials'!I18/'Historicial Financials'!H18-1,0) -> 0.28166484 | K7: =IFERROR(AVERAGE(D7:I7),0) -> 0.20131144 | L7: =IFERROR(MEDIAN(D7:I7),0) -> 0.20173521
B8: EBT Growth | D8: =IFERROR('Historicial Financials'!D27/'Historicial Financials'!C27-1,0) -> -0.25506836 | E8: =IFERROR('Historicial Financials'!E27/'Historicial Financials'!D27-1,0) -> 0.56314024 | F8: =IFERROR('Historicial Financials'!F27/'Historicial Financials'!E27-1,0) -> 0.50226096 | G8: =IFERROR('Historicial Financials'!G27/'Historicial Financials'!F27-1,0) -> 0.12311154 | H8: =IFERROR('Historicial Financials'!H27/'Historicial Financials'!G27-1,0) -> 0.057013904 | I8: =IFERROR('Historicial Financials'!I27/'Historicial Financials'!H27-1,0) -> 0.28950798 | K8: =IFERROR(AVERAGE(D8:I8),0) -> 0.21332771 | L8: =IFERROR(MEDIAN(D8:I8),0) -> 0.20630976
B9: Net Profit Growth | D9: =IFERROR('Historicial Financials'!D33/'Historicial Financials'!C33-1,0) -> -0.22752457 | E9: =IFERROR('Historicial Financials'!E33/'Historicial Financials'!D33-1,0) -> 0.54404916 | F9: =IFERROR('Historicial Financials'!F33/'Historicial Financials'!E33-1,0) -> 0.42574724 | G9: =IFERROR('Historicial Financials'!G33/'Historicial Financials'!F33-1,0) -> 0.17150434 | H9: =IFERROR('Historicial Financials'!H33/'Historicial Financials'!G33-1,0) -> 0.053584179 | I9: =IFERROR('Historicial Financials'!I33/'Historicial Financials'!H33-1,0) -> 0.25690004 | K9: =IFERROR(AVERAGE(D9:I9),0) -> 0.2040434 | L9: =IFERROR(MEDIAN(D9:I9),0) -> 0.21420219
B10: Dividend Growth | D10: =IFERROR('Historicial Financials'!D41/'Historicial Financials'!D41-1,0) -> 0 | E10: =IFERROR('Historicial Financials'!E41/'Historicial Financials'!E41-1,0) -> 0 | F10: =IFERROR('Historicial Financials'!F41/'Historicial Financials'!F41-1,0) -> 0 | G10: =IFERROR('Historicial Financials'!G41/'Historicial Financials'!G41-1,0) -> 0 | H10: =IFERROR('Historicial Financials'!H41/'Historicial Financials'!H41-1,0) -> 0 | I10: =IFERROR('Historicial Financials'!I41/'Historicial Financials'!I41-1,0) -> 0 | K10: =IFERROR(AVERAGE(D10:I10),0) -> 0 | L10: =IFERROR(MEDIAN(D10:I10),0) -> 0
B12: Gross Margin | C12: =IFERROR('Historicial Financials'!C13,0) -> 0.091985187 | D12: =IFERROR('Historicial Financials'!D13,0) -> 0.081015828 | E12: =IFERROR('Historicial Financials'!E13,0) -> 0.088453193 | F12: =IFERROR('Historicial Financials'!F13,0) -> 0.09247644 | G12: =IFERROR('Historicial Financials'!G13,0) -> 0.089190084 | H12: =IFERROR('Historicial Financials'!H13,0) -> 0.08409188 | I12: =IFERROR('Historicial Financials'!I13,0) -> 0.12815221 | K12: =IFERROR(AVERAGE(C12:I12),0) -> 0.093623546 | L12: =IFERROR(MEDIAN(D12:I12),0) -> 0.088821639
B13: Operating Margin | C13: =IFERROR('Historicial Financials'!C19,0) -> 0.078007817 | D13: =IFERROR('Historicial Financials'!D19,0) -> 0.065055134 | E13: =IFERROR('Historicial Financials'!E19,0) -> 0.074072508 | F13: =IFERROR('Historicial Financials'!F19,0) -> 0.077595335 | G13: =IFERROR('Historicial Financials'!G19,0) -> 0.07342264 | H13: =IFERROR('Historicial Financials'!H19,0) -> 0.06817542 | I13: =IFERROR('Historicial Financials'!I19,0) -> 0.075363764 | K13: =IFERROR(AVERAGE(C13:I13),0) -> 0.073098945 | L13: =IFERROR(MEDIAN(D13:I13),0) -> 0.073747574
B14: EBITDA Margin | C14: =IFERROR('Historicial Financials'!C19,0) -> 0.078007817 | D14: =IFERROR('Historicial Financials'!D19,0) -> 0.065055134 | E14: =IFERROR('Historicial Financials'!E19,0) -> 0.074072508 | F14: =IFERROR('Historicial Financials'!F19,0) -> 0.077595335 | G14: =IFERROR('Historicial Financials'!G19,0) -> 0.07342264 | H14: =IFERROR('Historicial Financials'!H19,0) -> 0.06817542 | I14: =IFERROR('Historicial Financials'!I19,0) -> 0.075363764 | K14: =IFERROR(AVERAGE(C14:I14),0) -> 0.073098945 | L14: =IFERROR(MEDIAN(D14:I14),0) -> 0.073747574
B15: EBIT Margin | C15: =IFERROR(('Historicial Financials'!C18-'Historicial Financials'!C24)/'Historicial Financials'!C6,0) -> 0.062953253 | D15: =IFERROR(('Historicial Financials'!D18-'Historicial Financials'!D24)/'Historicial Financials'!D6,0) -> 0.047900722 | E15: =IFERROR(('Historicial Financials'!E18-'Historicial Financials'!E24)/'Historicial Financials'!E6,0) -> 0.057993102 | F15: =IFERROR(('Historicial Financials'!F18-'Historicial Financials'!F24)/'Historicial Financials'!F6,0) -> 0.06268225 | G15: =IFERROR(('Historicial Financials'!G18-'Historicial Financials'!G24)/'Historicial Financials'!G6,0) -> 0.059034437 | H15: =IFERROR(('Historicial Financials'!H18-'Historicial Financials'!H24)/'Historicial Financials'!H6,0) -> 0.053526691 | I15: =IFERROR(('Historicial Financials'!I18-'Historicial Financials'!I24)/'Historicial Financials'!I6,0) -> 0.060295341 | K15: =IFERROR(AVERAGE(C15:I15),0) -> 0.0577694 | L15: =IFERROR(MEDIAN(D15:I15),0) -> 0.05851377
B16: EBT Margin | C16: =IFERROR('Historicial Financials'!C28,0) -> 0.060174024 | D16: =IFERROR('Historicial Financials'!D28,0) -> 0.046175588 | E16: =IFERROR('Historicial Financials'!E28,0) -> 0.056256612 | F16: =IFERROR('Historicial Financials'!F28,0) -> 0.061108704 | G16: =IFERROR('Historicial Financials'!G28,0) -> 0.057889894 | H16: =IFERROR('Historicial Financials'!H28,0) -> 0.052356673 | I16: =IFERROR('Historicial Financials'!I28,0) -> 0.058231283 | K16: =IFERROR(AVERAGE(C16:I16),0) -> 0.05602754 | L16: =IFERROR(MEDIAN(D16:I16),0) -> 0.057073253
B17: Net Profit Margin | C17: =IFERROR('Historicial Financials'!C34,0) -> 0.07801425 | D17: =IFERROR('Historicial Financials'!D34,0) -> 0.062079123 | E17: =IFERROR('Historicial Financials'!E34,0) -> 0.074708478 | F17: =IFERROR('Historicial Financials'!F34,0) -> 0.077018765 | G17: =IFERROR('Historicial Financials'!G34,0) -> 0.076105711 | H17: =IFERROR('Historicial Financials'!H34,0) -> 0.068608049 | I17: =IFERROR('Historicial Financials'!I34,0) -> 0.074376561 | K17: =IFERROR(AVERAGE(C17:I17),0) -> 0.072987277 | L17: =IFERROR(MEDIAN(D17:I17),0) -> 0.07454252
B19: SalesExpenses%Sales | C19: =IFERROR('Historicial Financials'!C16,0) -> 0.013977371 | D19: =IFERROR('Historicial Financials'!D16,0) -> 0.015960694 | E19: =IFERROR('Historicial Financials'!E16,0) -> 0.014380686 | F19: =IFERROR('Historicial Financials'!F16,0) -> 0.014881105 | G19: =IFERROR('Historicial Financials'!G16,0) -> 0.015767443 | H19: =IFERROR('Historicial Financials'!H16,0) -> 0.01591646 | I19: =IFERROR('Historicial Financials'!I16,0) -> 0.052788447 | K19: =IFERROR(AVERAGE(C19:I19),0) -> 0.020524601 | L19: =IFERROR(MEDIAN(D19:I19),0) -> 0.015841951
B20: Depreciation%Sales | C20: =IFERROR('Historicial Financials'!C25,0) -> 0.015054563 | D20: =IFERROR('Historicial Financials'!D25,0) -> 0.017154412 | E20: =IFERROR('Historicial Financials'!E25,0) -> 0.016079405 | F20: =IFERROR('Historicial Financials'!F25,0) -> 0.014913085 | G20: =IFERROR('Historicial Financials'!G25,0) -> 0.014388203 | H20: =IFERROR('Historicial Financials'!H25,0) -> 0.014648729 | I20: =IFERROR('Historicial Financials'!I25,0) -> 0.015068423 | K20: =IFERROR(AVERAGE(C20:I20),0) -> 0.015329546 | L20: =IFERROR(MEDIAN(D20:I20),0) -> 0.014990754
B21: OperatingIncome%Sales | C21: =IFERROR(C15,0) -> 0.062953253 | D21: =IFERROR(D15,0) -> 0.047900722 | E21: =IFERROR(E15,0) -> 0.057993102 | F21: =IFERROR(F15,0) -> 0.06268225 | G21: =IFERROR(G15,0) -> 0.059034437 | H21: =IFERROR(H15,0) -> 0.053526691 | I21: =IFERROR(I15,0) -> 0.060295341 | K21: =IFERROR(AVERAGE(C21:I21),0) -> 0.0577694 | L21: =IFERROR(MEDIAN(D21:I21),0) -> 0.05851377
B23: Return on Capital Employed | C23: =IFERROR(('Historicial Financials'!C18-'Historicial Financials'!C24)/SUM('Historicial Financials'!C47:C49),0) -> 0.137183 | D23: =IFERROR(('Historicial Financials'!D18-'Historicial Financials'!D24)/SUM('Historicial Financials'!D47:D49),0) -> 0.091955421 | E23: =IFERROR(('Historicial Financials'!E18-'Historicial Financials'!E24)/SUM('Historicial Financials'!E47:E49),0) -> 0.12540752 | F23: =IFERROR(('Historicial Financials'!F18-'Historicial Financials'!F24)/SUM('Historicial Financials'!F47:F49),0) -> 0.16058674 | G23: =IFERROR(('Historicial Financials'!G18-'Historicial Financials'!G24)/SUM('Historicial Financials'!G47:G49),0) -> 0.15543251 | H23: =IFERROR(('Historicial Financials'!H18-'Historicial Financials'!H24)/SUM('Historicial Financials'!H47:H49),0) -> 0.14281418 | I23: =IFERROR(('Historicial Financials'!I18-'Historicial Financials'!I24)/SUM('Historicial Financials'!I47:I49),0) -> 0.15432204 | K23: =IFERROR(AVERAGE(C23:I23),0) -> 0.13824306 | L23: =IFERROR(MEDIAN(D23:I23),0) -> 0.14856811
B24: Retained Earnings% | C24: =IFERROR('Historicial Financials'!C44,0) -> 1 | D24: =IFERROR('Historicial Financials'!D44,0) -> 1 | E24: =IFERROR('Historicial Financials'!E44,0) -> 1 | F24: =IFERROR('Historicial Financials'!F44,0) -> 1 | G24: =IFERROR('Historicial Financials'!G44,0) -> 1 | H24: =IFERROR('Historicial Financials'!H44,0) -> 1 | I24: =IFERROR('Historicial Financials'!I44,0) -> 1 | K24: =IFERROR(AVERAGE(C24:I24),0) -> 1 | L24: =IFERROR(MEDIAN(D24:I24),0) -> 1
B25: Return on Equity% | C25: =IFERROR('Historicial Financials'!C33/SUM('Historicial Financials'!C47:C48),0) -> 0.17511512 | D25: =IFERROR('Historicial Financials'!D33/SUM('Historicial Financials'!D47:D48),0) -> 0.12301508 | E25: =IFERROR('Historicial Financials'!E33/SUM('Historicial Financials'!E47:E48),0) -> 0.16919512 | F25: =IFERROR('Historicial Financials'!F33/SUM('Historicial Financials'!F47:F48),0) -> 0.20520627 | G25: =IFERROR('Historicial Financials'!G33/SUM('Historicial Financials'!G47:G48),0) -> 0.2067257 | H25: =IFERROR('Historicial Financials'!H33/SUM('Historicial Financials'!H47:H48),0) -> 0.19005449 | I25: =IFERROR('Historicial Financials'!I33/SUM('Historicial Financials'!I47:I48),0) -> 0.20923159 | K25: =IFERROR(AVERAGE(C25:I25),0) -> 0.18264905 | L25: =IFERROR(MEDIAN(D25:I25),0) -> 0.19763038
B26: Self Sustained Growth Rate | C26: =IFERROR(C24*C25,0) -> 0.17511512 | D26: =IFERROR(D24*D25,0) -> 0.12301508 | E26: =IFERROR(E24*E25,0) -> 0.16919512 | F26: =IFERROR(F24*F25,0) -> 0.20520627 | G26: =IFERROR(G24*G25,0) -> 0.2067257 | H26: =IFERROR(H24*H25,0) -> 0.19005449 | I26: =IFERROR(I24*I25,0) -> 0.20923159 | K26: =IFERROR(AVERAGE(C26:I26),0) -> 0.18264905 | L26: =IFERROR(MEDIAN(D26:I26),0) -> 0.19763038
B27: Interest Coverage Ratio | C27: =IFERROR(('Historicial Financials'!C18-'Historicial Financials'!C24)/'Historicial Financials'!C21,0) -> 22.651331 | D27: =IFERROR(('Historicial Financials'!D18-'Historicial Financials'!D24)/'Historicial Financials'!D21,0) -> 27.766387 | E27: =IFERROR(('Historicial Financials'!E18-'Historicial Financials'!E24)/'Historicial Financials'!E21,0) -> 33.396728 | F27: =IFERROR(('Historicial Financials'!F18-'Historicial Financials'!F24)/'Historicial Financials'!F21,0) -> 39.835039 | G27: =IFERROR(('Historicial Financials'!G18-'Historicial Financials'!G24)/'Historicial Financials'!G21,0) -> 51.579047 | H27: =IFERROR(('Historicial Financials'!H18-'Historicial Financials'!H24)/'Historicial Financials'!H21,0) -> 45.748596 | I27: =IFERROR(('Historicial Financials'!I18-'Historicial Financials'!I24)/'Historicial Financials'!I21,0) -> 29.212038 | K27: =IFERROR(AVERAGE(C27:I27),0) -> 35.741309 | L27: =IFERROR(MEDIAN(D27:I27),0) -> 36.615884
B29: Debtor Turnover Ratio | C29: =IFERROR('Historicial Financials'!C6/'Historicial Financials'!C59,0) -> 1272.133 | D29: =IFERROR('Historicial Financials'!D6/'Historicial Financials'!D59,0) -> 553.99403 | E29: =IFERROR('Historicial Financials'!E6/'Historicial Financials'!E59,0) -> 463.09269 | F29: =IFERROR('Historicial Financials'!F6/'Historicial Financials'!F59,0) -> 689.18211 | G29: =IFERROR('Historicial Financials'!G6/'Historicial Financials'!G59,0) -> 305.27637 | H29: =IFERROR('Historicial Financials'!H6/'Historicial Financials'!H59,0) -> 385.9682 | I29: =IFERROR('Historicial Financials'!I6/'Historicial Financials'!I59,0) -> 460.8326 | K29: =IFERROR(AVERAGE(C29:I29),0) -> 590.06843 | L29: =IFERROR(MEDIAN(D29:I29),0) -> 461.96264
B30: Creditor Turnover Ratio | C30: =IFERROR('Historicial Financials'!C6/'Historicial Financials'!C50,0) -> 37.498605 | D30: =IFERROR('Historicial Financials'!D6/'Historicial Financials'!D50,0) -> 22.383079 | E30: =IFERROR('Historicial Financials'!E6/'Historicial Financials'!E50,0) -> 27.020473 | F30: =IFERROR('Historicial Financials'!F6/'Historicial Financials'!F50,0) -> 30.979405 | G30: =IFERROR('Historicial Financials'!G6/'Historicial Financials'!G50,0) -> 26.979458 | H30: =IFERROR('Historicial Financials'!H6/'Historicial Financials'!H50,0) -> 28.739112 | I30: =IFERROR('Historicial Financials'!I6/'Historicial Financials'!I50,0) -> 26.115648 | K30: =IFERROR(AVERAGE(C30:I30),0) -> 28.530826 | L30: =IFERROR(MEDIAN(D30:I30),0) -> 26.999965
B31: Inventory Turnover Ratio | C31: =IFERROR('Historicial Financials'!C6/'Historicial Financials'!C60,0) -> 12.770977 | D31: =IFERROR('Historicial Financials'!D6/'Historicial Financials'!D60,0) -> 10.738458 | E31: =IFERROR('Historicial Financials'!E6/'Historicial Financials'!E60,0) -> 11.294244 | F31: =IFERROR('Historicial Financials'!F6/'Historicial Financials'!F60,0) -> 13.2079 | G31: =IFERROR('Historicial Financials'!G6/'Historicial Financials'!G60,0) -> 12.932218 | H31: =IFERROR('Historicial Financials'!H6/'Historicial Financials'!H60,0) -> 11.767188 | I31: =IFERROR('Historicial Financials'!I6/'Historicial Financials'!I60,0) -> 11.663267 | K31: =IFERROR(AVERAGE(C31:I31),0) -> 12.053464 | L31: =IFERROR(MEDIAN(D31:I31),0) -> 11.715228
B32: Fixed Assets Turnover Ratio | C32: =IFERROR('Historicial Financials'!C6/'Historicial Financials'!C53,0) -> 4.1812499 | D32: =IFERROR('Historicial Financials'!D6/'Historicial Financials'!D53,0) -> 3.4446781 | E32: =IFERROR('Historicial Financials'!E6/'Historicial Financials'!E53,0) -> 3.3451623 | F32: =IFERROR('Historicial Financials'!F6/'Historicial Financials'!F53,0) -> 3.7775791 | G32: =IFERROR('Historicial Financials'!G6/'Historicial Financials'!G53,0) -> 3.7859732 | H32: =IFERROR('Historicial Financials'!H6/'Historicial Financials'!H53,0) -> 3.6626166 | I32: =IFERROR('Historicial Financials'!I6/'Historicial Financials'!I53,0) -> 3.4255688 | K32: =IFERROR(AVERAGE(C32:I32),0) -> 3.660404 | L32: =IFERROR(MEDIAN(D32:I32),0) -> 3.5536474
B33: Capital Turnover Ratio | C33: =IFERROR('Historicial Financials'!C6/SUM('Historicial Financials'!C47:C48),0) -> 2.2446556 | D33: =IFERROR('Historicial Financials'!D6/SUM('Historicial Financials'!D47:D48),0) -> 1.9815852 | E33: =IFERROR('Historicial Financials'!E6/SUM('Historicial Financials'!E47:E48),0) -> 2.2647379 | F33: =IFERROR('Historicial Financials'!F6/SUM('Historicial Financials'!F47:F48),0) -> 2.6643671 | G33: =IFERROR('Historicial Financials'!G6/SUM('Historicial Financials'!G47:G48),0) -> 2.7162969 | H33: =IFERROR('Historicial Financials'!H6/SUM('Historicial Financials'!H47:H48),0) -> 2.7701485 | I33: =IFERROR('Historicial Financials'!I6/SUM('Historicial Financials'!I47:I48),0) -> 2.8131388 | K33: =IFERROR(AVERAGE(C33:I33),0) -> 2.4935614 | L33: =IFERROR(MEDIAN(D33:I33),0) -> 2.690332
B35: Debtor Days | C35: =IFERROR(365/C29,0) -> 0.28691969 | D35: =IFERROR(365/D29,0) -> 0.65885186 | E35: =IFERROR(365/E29,0) -> 0.78817914 | F35: =IFERROR(365/F29,0) -> 0.52961328 | G35: =IFERROR(365/G29,0) -> 1.1956379 | H35: =IFERROR(365/H29,0) -> 0.94567375 | I35: =IFERROR(365/I29,0) -> 0.79204467 | K35: =IFERROR(AVERAGE(C35:I35),0) -> 0.74241718 | L35: =IFERROR(MEDIAN(D35:I35),0) -> 0.79011191
B36: Payable Days | C36: =IFERROR(365/C30,0) -> 9.7336953 | D36: =IFERROR(365/D30,0) -> 16.306962 | E36: =IFERROR(365/E30,0) -> 13.508276 | F36: =IFERROR(365/F30,0) -> 11.782021 | G36: =IFERROR(365/G30,0) -> 13.528811 | H36: =IFERROR(365/H30,0) -> 12.700462 | I36: =IFERROR(365/I30,0) -> 13.976295 | K36: =IFERROR(AVERAGE(C36:I36),0) -> 13.076646 | L36: =IFERROR(MEDIAN(D36:I36),0) -> 13.518544
B37: Inventory Days | C37: =IFERROR(365/C31,0) -> 28.58043 | D37: =IFERROR(365/D31,0) -> 33.989983 | E37: =IFERROR(365/E31,0) -> 32.317348 | F37: =IFERROR(365/F31,0) -> 27.634976 | G37: =IFERROR(365/G31,0) -> 28.224083 | H37: =IFERROR(365/H31,0) -> 31.018456 | I37: =IFERROR(365/I31,0) -> 31.294834 | K37: =IFERROR(AVERAGE(C37:I37),0) -> 30.437158 | L37: =IFERROR(MEDIAN(D37:I37),0) -> 31.156645
B38: Cash Conversion Cycle | C38: =IFERROR(SUM(C35,C37)-C36,0) -> 19.133654 | D38: =IFERROR(SUM(D35,D37)-D36,0) -> 18.341873 | E38: =IFERROR(SUM(E35,E37)-E36,0) -> 19.597251 | F38: =IFERROR(SUM(F35,F37)-F36,0) -> 16.382568 | G38: =IFERROR(SUM(G35,G37)-G36,0) -> 15.890909 | H38: =IFERROR(SUM(H35,H37)-H36,0) -> 19.263668 | I38: =IFERROR(SUM(I35,I37)-I36,0) -> 18.110583 | K38: =IFERROR(AVERAGE(C38:I38),0) -> 18.10293 | L38: =IFERROR(MEDIAN(D38:I38),0) -> 18.226228
B40: CFO/Sales | C40: =IFERROR('Historicial Financials'!C76/'Historicial Financials'!C6,0) -> 0.036388931 | D40: =IFERROR('Historicial Financials'!D76/'Historicial Financials'!D6,0) -> 0.051691873 | E40: =IFERROR('Historicial Financials'!E76/'Historicial Financials'!E6,0) -> 0.025535676 | F40: =IFERROR('Historicial Financials'!F76/'Historicial Financials'!F6,0) -> 0.053945465 | G40: =IFERROR('Historicial Financials'!G76/'Historicial Financials'!G6,0) -> 0.041367364 | H40: =IFERROR('Historicial Financials'!H76/'Historicial Financials'!H6,0) -> 0.022760182 | I40: =IFERROR('Historicial Financials'!I76/'Historicial Financials'!I6,0) -> 0.040205903 | K40: =IFERROR(AVERAGE(C40:I40),0) -> 0.038842199 | L40: =IFERROR(MEDIAN(D40:I40),0) -> 0.040786633
B41: CFO/Total Asset | C41: =IFERROR('Historicial Financials'!C76/'Historicial Financials'!C63,0) -> 0.074941041 | D41: =IFERROR('Historicial Financials'!D76/'Historicial Financials'!D63,0) -> 0.091394759 | E41: =IFERROR('Historicial Financials'!E76/'Historicial Financials'!E63,0) -> 0.051127983 | F41: =IFERROR('Historicial Financials'!F76/'Historicial Financials'!F63,0) -> 0.12764768 | G41: =IFERROR('Historicial Financials'!G76/'Historicial Financials'!G63,0) -> 0.099232589 | H41: =IFERROR('Historicial Financials'!H76/'Historicial Financials'!H63,0) -> 0.055567483 | I41: =IFERROR('Historicial Financials'!I76/'Historicial Financials'!I63,0) -> 0.093719538 | K41: =IFERROR(AVERAGE(C41:I41),0) -> 0.084804439 | L41: =IFERROR(MEDIAN(D41:I41),0) -> 0.092557148
B42: CFO/Total Debt | C42: =IFERROR('Historicial Financials'!C76/'Historicial Financials'!C49,0) -> 2.716168 | D42: =IFERROR('Historicial Financials'!D76/'Historicial Financials'!D49,0) -> 3.1779175 | E42: =IFERROR('Historicial Financials'!E76/'Historicial Financials'!E49,0) -> 1.2226791 | F42: =IFERROR('Historicial Financials'!F76/'Historicial Financials'!F49,0) -> 3.594202 | G42: =IFERROR('Historicial Financials'!G76/'Historicial Financials'!G49,0) -> 3.5480276 | H42: =IFERROR('Historicial Financials'!H76/'Historicial Financials'!H49,0) -> 1.6483248 | I42: =IFERROR('Historicial Financials'!I76/'Historicial Financials'!I49,0) -> 1.1410356 | K42: =IFERROR(AVERAGE(C42:I42),0) -> 2.4354792 | L42: =IFERROR(MEDIAN(D42:I42),0) -> 2.4131212

Sheet Forecasting
B2: ='Data Sheet'!B1 & " Forcaste" & "-" & 'Data Sheet'!A17 -> AVENUE SUPERMARTS LTD Forcaste-Sales | G2: ='Data Sheet'!B1 & " Forcaste" & "-" & 'Historicial Financials'!B18 -> AVENUE SUPERMARTS LTD Forcaste-EBITDA
B3: Year Weight | C3: Year | D3: Sales | E3: Sales Growth | G3: Year Weight | H3: Year | I3: EBITDA | J3: EBITDA Growth
B4: 1 | C4: ='Data Sheet'!E16 -> 43921 | D4: {=TRANSPOSE('Historicial Financials'!C6:I6)} -> 24870.2 | G4: 1 | H4: ='Data Sheet'!E16 -> 43921 | I4: {=TRANSPOSE('Historicial Financials'!C18:I18)} -> 1940.07
B5: =B4+1 -> 2 | C5: =C4+365 -> 44286 | D5: 24143.06 | E5: =IFERROR(D5/D4-1,0) -> -0.029237401 | G5: =G4+1 -> 2 | H5: =H4+365 -> 44286 | I5: 1570.63 | J5: =IFERROR(I5/I4-1,0) -> -0.19042612
B6: =B5+1 -> 3 | C6: =C5+365 -> 44651 | D6: 30976.27 | E6: =IFERROR(D6/D5-1,0) -> 0.28302999 | G6: =G5+1 -> 3 | H6: =H5+365 -> 44651 | I6: 2294.49 | J6: =IFERROR(I6/I5-1,0) -> 0.46087239
B7: =B6+1 -> 4 | C7: =C6+365 -> 45016 | D7: 42839.56 | E7: =IFERROR(D7/D6-1,0) -> 0.38297994 | G7: =G6+1 -> 4 | H7: =H6+365 -> 45016 | I7: 3324.15 | J7: =IFERROR(I7/I6-1,0) -> 0.44875332
B8: =B7+1 -> 5 | C8: =C7+365 -> 45381 | D8: 50788.83 | E8: =IFERROR(D8/D7-1,0) -> 0.1855591 | G8: =G7+1 -> 5 | H8: =H7+365 -> 45381 | I8: 3729.05 | J8: =IFERROR(I8/I7-1,0) -> 0.12180557
B9: =B8+1 -> 6 | C9: =C8+365 -> 45746 | D9: 59358.05 | E9: =IFERROR(D9/D8-1,0) -> 0.16872253 | G9: =G8+1 -> 6 | H9: =H8+365 -> 45746 | I9: 4046.76 | J9: =IFERROR(I9/I8-1,0) -> 0.085198643
B10: =B9+1 -> 7 | C10: =C9+365 -> 46111 | D10: 68820.74 | E10: =IFERROR(D10/D9-1,0) -> 0.15941713 | G10: =G9+1 -> 7 | H10: =H9+365 -> 46111 | I10: 5186.59 | J10: =IFERROR(I10/I9-1,0) -> 0.28166484
B11: =B10+1 -> 8 | C11: =C10+365 -> 46476 | D11: =FORECAST(B11,$D$4:$D$10,$B$4:$B$10) -> 74841.553 | E11: =IFERROR(D11/D10-1,0) -> 0.087485442 | G11: =G10+1 -> 8 | H11: =H10+365 -> 46476 | I11: =FORECAST(G11,$I$4:$I$10,$G$4:$G$10) -> 5459.7314 | J11: =IFERROR(I11/I10-1,0) -> 0.052663008
B12: =B11+1 -> 9 | C12: =C11+365 -> 46841 | D12: =FORECAST(B12,$D$4:$D$10,$B$4:$B$10) -> 82773.487 | E12: =IFERROR(D12/D11-1,0) -> 0.10598303 | G12: =G11+1 -> 9 | H12: =H11+365 -> 46841 | I12: =FORECAST(G12,$I$4:$I$10,$G$4:$G$10) -> 6035.6736 | J12: =IFERROR(I12/I11-1,0) -> 0.1054891
B13: =B12+1 -> 10 | C13: =C12+365 -> 47206 | D13: =FORECAST(B13,$D$4:$D$10,$B$4:$B$10) -> 90705.421 | E13: =IFERROR(D13/D12-1,0) -> 0.095826992 | G13: =G12+1 -> 10 | H13: =H12+365 -> 47206 | I13: =FORECAST(G13,$I$4:$I$10,$G$4:$G$10) -> 6611.6157 | J13: =IFERROR(I13/I12-1,0) -> 0.095423011
B14: =B13+1 -> 11 | C14: =C13+365 -> 47571 | D14: =FORECAST(B14,$D$4:$D$10,$B$4:$B$10) -> 98637.356 | E14: =IFERROR(D14/D13-1,0) -> 0.087447191 | G14: =G13+1 -> 11 | H14: =H13+365 -> 47571 | I14: =FORECAST(G14,$I$4:$I$10,$G$4:$G$10) -> 7187.5579 | J14: =IFERROR(I14/I13-1,0) -> 0.08711065
B15: =B14+1 -> 12 | C15: =C14+365 -> 47936 | D15: =FORECAST(B15,$D$4:$D$10,$B$4:$B$10) -> 106569.29 | E15: =IFERROR(D15/D14-1,0) -> 0.080415115 | G15: =G14+1 -> 12 | H15: =H14+365 -> 47936 | I15: =FORECAST(G15,$I$4:$I$10,$G$4:$G$10) -> 7763.5 | J15: =IFERROR(I15/I14-1,0) -> 0.080130436

Sheet WACC
B2: Weighted Average Cost of Capital
B4: All figures are in INR unless stated otherwise
B6: Peer Comps
G8: Debt/ | H8: Debt/ | I8: Levered | J8: Unlevered
B9: Name of Company | C9: Country | D9: Total Debt | E9: Total Equity | F9: Tax Rate 1 | G9: Equity | H9: Capital | I9: Beta 2 | J9: Beta 3
B11: Avenue Super. | C11: India | D11: 2424.99 | E11: 652.25 | F11: 0.3 | G11: =D11/E11 -> 3.7178842 | H11: =D11/(D11+E11) -> 0.78804058 | I11: =Beta!N7 -> 0.70010611 | J11: =I11/(1+(1-F11)*G11) -> 0.19433794
B12: Vishal Mega Mart | C12: India | D12: 1987.98 | E12: 4676.38 | F12: 0.3 | G12: =D12/E12 -> 0.42511088 | H12: =D12/(D12+E12) -> 0.29830021 | I12: =Beta!AK7 -> 1.1280229 | J12: =I12/(1+(1-F12)*G12) -> 0.8693298
E14: Average | F14: =AVERAGE(F11:F12) -> 0.3 | G14: =AVERAGE(G11:G12) -> 2.0714976 | H14: =AVERAGE(H11:H12) -> 0.5431704 | I14: =AVERAGE(I11:I11) -> 0.70010611 | J14: =AVERAGE(J11:J12) -> 0.53183387
E15: Median | F15: =MEDIAN(F11:F12) -> 0.3 | G15: =MEDIAN(G11:G12) -> 2.0714976 | H15: =MEDIAN(H11:H12) -> 0.5431704 | I15: =MEDIAN(I11:I11) -> 0.70010611 | J15: =MEDIAN(J11:J12) -> 0.53183387
B19: Cost of Debt | G19: Cost of Equity
B21: Pre Tax Cost of Debt | C21: =142/D11 -> 0.058556943 | G21: Risk Free Rate | I21: 0.0677 | J21: Taken from 10 yrs yield of govt. bond
B22: Tax Rate | C22: =F14 -> 0.3 | G22: Equity Risk Premium | I22: =Beta!Y9-WACC!I21 -> 0.083792308
B23: Post Tax Cost of Debt | C23: =C21*(1-C22) -> 0.04098986 | G23: Levered Beta 4 | I23: =J32 -> 0.97447919
G24: Cost of Equity | I24: =I21+(I22*I23) -> 0.14935386
B27: Capital Structure | G27: Levered Beta
D29: Current | E29: Target | G29: Comps Median Unlevered Beta | J29: =J15 -> 0.53183387
B30: Total Debt | C30: =D12 -> 1987.98 | D30: =C30/$C$32 -> 0.29830021 | E30: =H15 -> 0.5431704 | G30: Target Debt/Equity | J30: =E35 -> 1.189
B31: Market Capitalization | C31: =E12 -> 4676.38 | D31: =C31/$C$32 -> 0.70169979 | E31: =1-E30 -> 0.4568296 | G31: Tax Rate | J31: =F11 -> 0.3
B32: Total Capital | C32: =SUM(C30:C31) -> 6664.36 | D32: =SUM(D30:D31) -> 1 | E32: =SUM(E30:E31) -> 1 | G32: Levered Beta | J32: =J29*(1+(1-J31)*J30) -> 0.97447919
B35: Debt/Equity | D35: =D30/D31 -> 0.42511088 | E35: =E30/E31 -> 1.189 | G35: Weighted Average Cost of Capital
I36: Total Cost | J36: Total Weight
B37: Note: | G37: Debt | I37: =C23 -> 0.04098986 | J37: =E30 -> 0.5431704
B38: 1. Tax Rate Consider as Marginal Tax Rate for the company | G38: Equity | I38: =I24 -> 0.14935386 | J38: =E31 -> 0.4568296
B39: 2. Levered Beta is based on 5 year montly data | G39: Weighted Average Cost of Capital | J39: =SUMPRODUCT(I37:I38,J37:J38) -> 0.090493743

Sheet Beta
B2: ="Beta Calculation-"&'Data Sheet'!B1 -> Beta Calculation-AVENUE SUPERMARTS LTD
B4: Avenue Weekly Return | F4: Nifty Weekly Return | U4: Rm Calulation | AB4: Vishal Mega Mart Weekly Return
B6: Date | C6: Price | D6: Weekly Return | F6: Date | G6: Price | H6: Weekly Return | J6: Beta Drifting | U6: Year | V6: Annual | AB6: Date | AC6: Price | AD6: Weekly Return | AF6: Beta Drifting
B7: 46222 | C7: 4018.8 | F7: 46222 | G7: 23869.6 | M7: Beta 1 | N7: =SLOPE(D8:D110,H8:H110) -> 0.70010611 | U7: 2000 | V7: -0.1465 | X7: Average Return | Y7: =AVERAGE(V7:V32) -> 0.15149231 | AB7: 46222 | AC7: 108.04 | AJ7: Beta | AK7: =SLOPE(AD8:AD89,H8:H89) -> 1.1280229
B8: 46215 | C8: 3951.9 | D8: =C8/C7-1 -> -0.01664676 | F8: 46215 | G8: 24334.3 | H8: =G8/G7-1 -> 0.019468278 | J8: Levered Raw Beta | K8: =N10 -> 0.70010611 | M8: Beta 2 | N8: =_xlfn.COVARIANCE.S(D8:D110,H8:H110)/_xlfn.VAR.S(H8:H110) -> 0.70010611 | U8: 2001 | V8: -0.1618 | X8: Dividend Yield | Y8: 1.30 1 | AB8: 46215 | AC8: 110.33 | AD8: =AC8/AC7-1 -> 0.021195853 | AF8: Levered Raw Beta | AG8: =AK7 -> 1.1280229
B9: 46208 | C9: 4081.1 | D9: =C9/C8-1 -> 0.032693135 | F9: 46208 | G9: 24206.9 | H9: =G9/G8-1 -> -0.0052354085 | J9: Raw Beta Weight | K9: 0.75 | U9: 2002 | V9: 0.0325 | X9: Total Market Return | Y9: =SUM(Y7:Y8) -> 0.15149231 | AB9: 46208 | AC9: 118.79 | AD9: =AC9/AC8-1 -> 0.076679054 | AF9: Raw Beta Weight | AG9: 0.75
B10: 46201 | C10: 3994.4 | D10: =C10/C9-1 -> -0.021244272 | F10: 46201 | G10: 24270.85 | H10: =G10/G9-1 -> 0.0026418087 | J10: Market Beta | K10: 1 | M10: Beta 3 | N10: =K36 -> 0.70010611 | U10: 2003 | V10: 0.719 | AB10: 46201 | AC10: 120.57 | AD10: =AC10/AC9-1 -> 0.014984426 | AF10: Market Beta | AG10: 1
B11: 46194 | C11: 4294.6 | D11: =C11/C10-1 -> 0.075155217 | F11: 46194 | G11: 24056 | H11: =G11/G10-1 -> -0.0088521828 | J11: Market Beta Weight | K11: =1-K9 -> 0.25 | U11: 2004 | V11: 0.1068 | AB11: 46194 | AC11: 116.39 | AD11: =AC11/AC10-1 -> -0.034668657 | AF11: Market Beta Weight | AG11: =1-AG9 -> 0.25
B12: 46187 | C12: 4286.9 | D12: =C12/C11-1 -> -0.0017929493 | F12: 46187 | G12: 24013.1 | H12: =G12/G11-1 -> -0.0017833389 | U12: 2005 | V12: 0.3634 | AB12: 46187 | AC12: 118.66 | AD12: =AC12/AC11-1 -> 0.019503394
B13: 46180 | C13: 3993.6 | D13: =C13/C12-1 -> -0.068417738 | F13: 46180 | G13: 23622.9 | H13: =G13/G12-1 -> -0.016249464 | J13: Adjusted Beta | K13: =(K8*K9)+(K10*K11) -> 0.77507958 | U13: 2006 | V13: 0.3983 | AB13: 46180 | AC13: 119.77 | AD13: =AC13/AC12-1 -> 0.0093544581 | AF13: Adjusted Beta | AG13: =(AG8*AG9)+(AG10*AG11) -> 1.0960172
B14: 46173 | C14: 4144.2 | D14: =C14/C13-1 -> 0.037710337 | F14: 46173 | G14: 23366.7 | H14: =G14/G13-1 -> -0.010845408 | U14: 2007 | V14: 0.5477 | AB14: 46173 | AC14: 118.73 | AD14: =AC14/AC13-1 -> -0.0086833097
B15: 46166 | C15: 4054.5 | D15: =C15/C14-1 -> -0.021644708 | F15: 46166 | G15: 23547.75 | H15: =G15/G14-1 -> 0.0077482058 | U15: 2008 | V15: -0.5179 | AB15: 46166 | AC15: 121.77 | AD15: =AC15/AC14-1 -> 0.025604312
B16: 46159 | C16: 4117 | D16: =C16/C15-1 -> 0.015414971 | F16: 46159 | G16: 23719.3 | H16: =G16/G15-1 -> 0.0072851971 | U16: 2009 | V16: 0.7576 | AB16: 46159 | AC16: 121.66 | AD16: =AC16/AC15-1 -> -0.00090334237
B17: 46152 | C17: 4358.7 | D17: =C17/C16-1 -> 0.058707797 | F17: 46152 | G17: 23643.5 | H17: =G17/G16-1 -> -0.0031957098 | U17: 2010 | V17: 0.1795 | AB17: 46152 | AC17: 118.99 | AD17: =AC17/AC16-1 -> -0.021946408
B18: 46145 | C18: 4402.1 | D18: =C18/C17-1 -> 0.0099570973 | F18: 46145 | G18: 24176.15 | H18: =G18/G17-1 -> 0.02252839 | U18: 2011 | V18: -0.2462 | AB18: 46145 | AC18: 123.93 | AD18: =AC18/AC17-1 -> 0.041516094
B19: 46138 | C19: 4585.9 | D19: =C19/C18-1 -> 0.0417528 | F19: 46138 | G19: 23997.55 | H19: =G19/G18-1 -> -0.0073874459 | J19: SUMMARY OUTPUT | U19: 2012 | V19: 0.277 | AB19: 46138 | AC19: 122.29 | AD19: =AC19/AC18-1 -> -0.013233277
B20: 46131 | C20: 4443.5 | D20: =C20/C19-1 -> -0.031051702 | F20: 46131 | G20: 23897.95 | H20: =G20/G19-1 -> -0.0041504237 | U20: 2013 | V20: 0.0676 | AB20: 46131 | AC20: 123.34 | AD20: =AC20/AC19-1 -> 0.0085861477
B21: 46124 | C21: 4628.5 | D21: =C21/C20-1 -> 0.041633847 | F21: 46124 | G21: 24353.55 | H21: =G21/G20-1 -> 0.019064397 | J21: Regression Statistics | U21: 2014 | V21: 0.3139 | AB21: 46124 | AC21: 118.95 | AD21: =AC21/AC20-1 -> -0.035592671
B22: 46117 | C22: 4400.6 | D22: =C22/C21-1 -> -0.049238414 | F22: 46117 | G22: 24050.6 | H22: =G22/G21-1 -> -0.012439665 | J22: Multiple R | K22: 0.31165003 | U22: 2015 | V22: -0.0406 | AB22: 46117 | AC22: 114.5 | AD22: =AC22/AC21-1 -> -0.037410677
B23: 46110 | C23: 4362.4 | D23: =C23/C22-1 -> -0.0086806345 | F23: 46110 | G23: 22713.1 | H23: =G23/G22-1 -> -0.055611918 | J23: R Square | K23: 0.097125743 | U23: 2016 | V23: 0.0301 | AB23: 46110 | AC23: 107.88 | AD23: =AC23/AC22-1 -> -0.057816594
B24: 46103 | C24: 3903.2 | D24: =C24/C23-1 -> -0.10526316 | F24: 46103 | G24: 22819.6 | H24: =G24/G23-1 -> 0.004688924 | J24: Adjusted R Square | K24: 0.088186394 | U24: 2017 | V24: 0.2865 | AB24: 46103 | AC24: 106.37 | AD24: =AC24/AC23-1 -> -0.013997034
B25: 46096 | C25: 3770.8 | D25: =C25/C24-1 -> -0.033920885 | F25: 46096 | G25: 23114.5 | H25: =G25/G24-1 -> 0.012923101 | J25: Standard Error | K25: 0.03928925 | U25: 2018 | V25: 0.0315 | AB25: 46096 | AC25: 102.3 | AD25: =AC25/AC24-1 -> -0.038262668
B26: 46089 | C26: 3834.3 | D26: =C26/C25-1 -> 0.016839928 | F26: 46089 | G26: 23151.1 | H26: =G26/G25-1 -> 0.0015834217 | J26: Observations | K26: 103 | U26: 2019 | V26: 0.1202 | AB26: 46089 | AC26: 102.79 | AD26: =AC26/AC25-1 -> 0.0047898338
B27: 46082 | C27: 3875.8 | D27: =C27/C26-1 -> 0.010823358 | F27: 46082 | G27: 24450.45 | H27: =G27/G26-1 -> 0.056124763 | U27: 2020 | V27: 0.149 | AB27: 46082 | AC27: 111.85 | AD27: =AC27/AC26-1 -> 0.08814087
B28: 46075 | C28: 3847.6 | D28: =C28/C27-1 -> -0.0072759172 | F28: 46075 | G28: 25178.65 | H28: =G28/G27-1 -> 0.029782683 | J28: ANOVA | U28: 2021 | V28: 0.2412 | AB28: 46075 | AC28: 117.78 | AD28: =AC28/AC27-1 -> 0.053017434
B29: 46068 | C29: 3866.4 | D29: =C29/C28-1 -> 0.0048861628 | F29: 46068 | G29: 25571.25 | H29: =G29/G28-1 -> 0.015592575 | K29: df | L29: SS | M29: MS | N29: F | O29: Significance F | U29: 2022 | V29: 0.0432 | AB29: 46068 | AC29: 116.9 | AD29: =AC29/AC28-1 -> -0.0074715571
B30: 46061 | C30: 3909.2 | D30: =C30/C29-1 -> 0.011069729 | F30: 46061 | G30: 25471.1 | H30: =G30/G29-1 -> -0.0039165078 | J30: Regression | K30: 1 | L30: 0.016771656 | M30: 0.016771656 | N30: 10.864968 | O30: 0.0013529537 | P30: Upper 95% | U30: 2023 | V30: 0.1942 | AB30: 46061 | AC30: 121.91 | AD30: =AC30/AC29-1 -> 0.042857143
B31: 46054 | C31: 3889.9 | D31: =C31/C30-1 -> -0.0049370715 | F31: 46054 | G31: 25693.7 | H31: =G31/G30-1 -> 0.0087393163 | J31: Residual | K31: 101 | L31: 0.15590816 | M31: 0.0015436452 | P31: 0.010111791 | U31: 2024 | V31: 0.0875 | AB31: 46054 | AC31: 122.19 | AD31: =AC31/AC30-1 -> 0.0022967763
B32: 46047 | C32: 3689.5 | D32: =C32/C31-1 -> -0.051518034 | F32: 46047 | G32: 25320.65 | H32: =G32/G31-1 -> -0.014519123 | J32: Total | K32: 102 | L32: 0.17267982 | P32: 1.1214458 | U32: 2025 | V32: 0.1051 | AB32: 46047 | AC32: 125.95 | AD32: =AC32/AC31-1 -> 0.030771749
B33: 46040 | C33: 3665.6 | D33: =C33/C32-1 -> -0.0064778425 | F33: 46040 | G33: 25048.65 | H33: =G33/G32-1 -> -0.01074222 | AB33: 46040 | AC33: 124.58 | AD33: =AC33/AC32-1 -> -0.010877332
B34: 46033 | C34: 3775.7 | D34: =C34/C33-1 -> 0.03003601 | F34: 46033 | G34: 25694.35 | H34: =G34/G33-1 -> 0.025777836 | K34: Coefficients | L34: Standard Error | M34: t Stat | N34: P-value | O34: Lower 95% | Q34: Lower 95.0% | R34: Upper 95.0% | AB34: 46033 | AC34: 129.54 | AD34: =AC34/AC33-1 -> 0.039813774
B35: 46026 | C35: 3801.3 | D35: =C35/C34-1 -> 0.0067801997 | F35: 46026 | G35: 25683.3 | H35: =G35/G34-1 -> -0.00043005563 | J35: Intercept | K35: 0.0024292594 | L35: 0.0038727691 | M35: 0.62726678 | N35: 0.53189987 | O35: -0.0052532727 | Q35: -0.0052532727 | R35: 0.010111791 | AB35: 46026 | AC35: 129.19 | AD35: =AC35/AC34-1 -> -0.0027018681
B36: 46019 | C36: 3719.8 | D36: =C36/C35-1 -> -0.021440034 | F36: 46019 | G36: 26328.55 | H36: =G36/G35-1 -> 0.025123329 | J36: X Variable 1 | K36: 0.70010611 | L36: 0.21239762 | M36: 3.2962051 | N36: 0.0013529537 | O36: 0.27876637 | Q36: 0.27876637 | R36: 1.1214458 | AB36: 46019 | AC36: 135.95 | AD36: =AC36/AC35-1 -> 0.052326031
B37: 46012 | C37: 3787.4 | D37: =C37/C36-1 -> 0.01817302 | F37: 46012 | G37: 26042.3 | H37: =G37/G36-1 -> -0.010872228 | AB37: 46012 | AC37: 136.26 | AD37: =AC37/AC36-1 -> 0.0022802501
B38: 46005 | C38: 3819.5 | D38: =C38/C37-1 -> 0.0084754713 | F38: 46005 | G38: 25966.4 | H38: =G38/G37-1 -> -0.0029144891 | AB38: 46005 | AC38: 138.07 | AD38: =AC38/AC37-1 -> 0.013283429
