Workbook
Name BoxPlot: "BoxPlot"
Name Bubble: "Bubble"
Name Candlestick: "Candlestick"
Name Chart: "Chart"
Name ChartImage: "ChartImage"
Name ColumnRange: "ColumnRange"
Name Dumbbell: "Dumbbell"
Name Heatmap: "Heatmap"
Name Histogram: "Histogram"
Name Map: "Map"
Name OHLC: "OHLC"
Name PieChart: "PieChart"
Name Scatter: "Scatter"
Name Series: "Series"
Name Stripe: "Stripe"
Name Table: "Table"
Name TreeMap: "TreeMap"
Name UPDATE: 'Data Sheet'!$E$1
Name Waterfall: "Waterfall"

Sheet Teaser
B2: ='Data Sheet'!B1&"- One Page" -> INDIAN HOTELS CO LTD- One Page
B4: #VALUE! | C4: IHCL is one of India’s leading hospitality companies. IHCL and its subsidiaries comprise diversified portfolio across luxury, upscale/upper upscale and lean luxury/midscale segments. IHCL’s operations are spread across four continents, 12 countries and over 100 cities.
B6: Key Metrics | C6: ='Data Sheet'!G16 -> 44651 | D6: ='Data Sheet'!H16 -> 45016 | E6: ='Data Sheet'!I16 -> 45382 | F6: ='Data Sheet'!J16 -> 45747 | G6: ='Data Sheet'!K16 -> 46112 | I6: Share Price 5 Years
B8: Total Sales | C8: ='Data Sheet'!G17 -> 3056.22 | D8: ='Data Sheet'!H17 -> 5809.91 | E8: ='Data Sheet'!I17 -> 6768.75 | F8: ='Data Sheet'!J17 -> 8334.54 | G8: ='Data Sheet'!K17 -> 9689.22
B9: Sales Growth | C9: ='Historicial Financials'!E8 -> 0.94026004 | D9: ='Historicial Financials'!F8 -> 0.90101171 | E9: ='Historicial Financials'!G8 -> 0.16503526 | F9: ='Historicial Financials'!H8 -> 0.23132632 | G9: ='Historicial Financials'!I8 -> 0.16253806
B10: Gross Margin | C10: ='Historicial Financials'!E14 -> 0.27696959 | D10: ='Historicial Financials'!F14 -> 0.41304254 | E10: ='Historicial Financials'!G14 -> 0.425306 | F10: ='Historicial Financials'!H14 -> 0.47245799 | G10: ='Historicial Financials'!I14 -> 0.47542836
B11: EBITDA Margin | C11: ='Historicial Financials'!E20 -> 0.13243484 | D11: ='Historicial Financials'!F20 -> 0.31060034 | E11: ='Historicial Financials'!G20 -> 0.31904118 | F11: ='Historicial Financials'!H20 -> 0.33227149 | G11: ='Historicial Financials'!I20 -> 0.32983047
B12: EBIT Margin | C12: ='Ratio Analysis'!E15 -> -0.00042536205 | D12: ='Ratio Analysis'!F15 -> 0.23898821 | E12: ='Ratio Analysis'!G15 -> 0.25192392 | F12: ='Ratio Analysis'!H15 -> 0.27010129 | G12: ='Ratio Analysis'!I15 -> 0.26737343
B13: Net Profit Margin | C13: ='Historicial Financials'!E35 -> -0.13693386 | D13: ='Historicial Financials'!F35 -> 0.14809179 | E13: ='Historicial Financials'!G35 -> 0.15933961 | F13: ='Historicial Financials'!H35 -> 0.16465576 | G13: ='Historicial Financials'!I35 -> 0.15768142
B14: EPS | C14: ='Historicial Financials'!E39 -> -2.9463531 | D14: ='Historicial Financials'!F39 -> 6.0574486 | E14: ='Historicial Financials'!G39 -> 7.5771392 | F14: ='Historicial Financials'!H39 -> 9.6412112 | G14: ='Historicial Financials'!I39 -> 10.733525
B15: EPS Growth | C15: ='Historicial Financials'!E40 -> -0.6273559 | D15: ='Historicial Financials'!F40 -> -3.055914 | E15: ='Historicial Financials'!G40 -> 0.25087966 | F15: ='Historicial Financials'!H40 -> 0.27240781 | G15: ='Historicial Financials'!I40 -> 0.11329636
B17: Income Segment | C17: =C6 -> 44651 | D17: =D6 -> 45016 | E17: =E6 -> 45382 | F17: =F6 -> 45747 | G17: =G6 -> 46112 | I17: RevPAR
B19: Room Income | C19: 848.19 | D19: 1594.04 | E19: 1952.72 | F19: 2238.42 | G19: 2374.64
B20: Food, Beverage & Banqueting Income | C20: 714.47 | D20: 1381.47 | E20: 1562.9 | F20: 1650.32 | G20: 1803.48
B21: Other Operating Income | C21: 242.03 | D21: 338.08 | E21: 426.7 | F21: 483.94 | G21: 557.22
B22: Management & Reimbursable Fees | C22: 198.65 | D22: 390.65 | E22: 463.28 | F22: 543.86 | G22: 644.21
B23: Non-operating Income | C23: 149.08 | D23: 107.08 | E23: 184.51 | F23: 228.55 | G23: 260.61
B24: Total Income | C24: 2152.42 | D24: 3811.32 | E24: 4590.11 | F24: 5145.09 | G24: 5640.16
B27: Other Ratios | C27: =C17 -> 44651 | D27: =D17 -> 45016 | E27: =E17 -> 45382 | F27: =F17 -> 45747 | G27: =G17 -> 46112 | I27: Like for Like Growth
B29: Inventory Turnover | C29: ='Ratio Analysis'!E32 -> 22.81493 | D29: ='Ratio Analysis'!F32 -> 32.471624 | E29: ='Ratio Analysis'!G32 -> 34.47782 | F29: ='Ratio Analysis'!H32 -> 34.907864 | G29: ='Ratio Analysis'!I32 -> 35.642987
B30: Working Capital | C30: ='Ratio Analysis'!E31 -> 0.75245624 | D30: ='Ratio Analysis'!F31 -> 0.67295813 | E30: ='Ratio Analysis'!G31 -> 0.81809379 | F30: ='Ratio Analysis'!H31 -> 0.88042421 | G30: ='Ratio Analysis'!I31 -> 0.62507272
B31: Inventory Days | C31: ='Ratio Analysis'!E38 -> 15.998296 | D31: ='Ratio Analysis'!F38 -> 11.240583 | E31: ='Ratio Analysis'!G38 -> 10.586516 | F31: ='Ratio Analysis'!H38 -> 10.456097 | G31: ='Ratio Analysis'!I38 -> 10.240444
B32: Cash Conversion Cycle | C32: ='Ratio Analysis'!E39 -> -198.56469 | D32: ='Ratio Analysis'!F39 -> -110.92763 | E32: ='Ratio Analysis'!G39 -> -100.71752 | F32: ='Ratio Analysis'!H39 -> -108.66791 | G32: ='Ratio Analysis'!I39 -> -125.5648
B36: Category | C36: # of Shares | D36: % of holding | E36: Value (CMP) | I36: Holding Share
B38: Promoters | C38: 5076.5531 | D38: 0.3566 | E38: =C38*'Data Sheet'!$B$8 -> 3644965.1
B39: Other Entities of the Promoter Group | C39: 349.02429 | D39: 0.0245 | E39: =C39*'Data Sheet'!$B$8 -> 250599.44
B40: Mutual Funds & UTI | C40: 1844.814 | D40: 0.1296 | E40: =C40*'Data Sheet'!$B$8 -> 1324576.4
B41: Banks, Financial Institutions, States and Central Government | C41: 659.6312 | D41: 0.0464 | E41: =C41*'Data Sheet'!$B$8 -> 473615.2
B42: Insurance Companies | C42: 704.90071 | D42: 0.0495 | E42: =C42*'Data Sheet'!$B$8 -> 506118.71
B43: Foreign Institutional Investors and Foreign Portfolio Investors – Corporate | C43: 3308.4461 | D43: 0.2324 | E43: =C43*'Data Sheet'!$B$8 -> 2375464.3
B44: NRI's / OCB's / Foreign Nationals | C44: 123.35274 | D44: 0.0087 | E44: =C44*'Data Sheet'!$B$8 -> 88567.267
B45: Corporate Bodies / Trust | C45: 149.28531 | D45: 0.0105 | E45: =C45*'Data Sheet'!$B$8 -> 107186.85
B46: Indian Public & Others | C46: 1967.2175 | D46: 0.1382 | E46: =C46*'Data Sheet'!$B$8 -> 1412462.2
B47: Alternate Investment Fund | C47: 18.59488 | D47: 0.0013 | E47: =C47*'Data Sheet'!$B$8 -> 13351.124
B48: IEPF account | C48: 32.50242 | D48: 0.0023 | E48: =C48*'Data Sheet'!$B$8 -> 23336.738
B50: Top Shareholders | C50: Designation | D50: Remuneration | E50: X of Median Salary | I50: Capital Structure
B52: Mr. Puneet Chhatwal | C52: MD & CEO | E52: 521.17
B53: Mr. Nasser Munjee | C53: Non Executive | D53: 6.14 | E53: 18.7 | I53: Share Price | J53: ='Data Sheet'!B8 -> 718
B54: Mr. Venkataramanan | C54: Non Executive | D54: 2.57 | E54: 17.8 | I54: No. of Share O/S | J54: ='Data Sheet'!B6 -> 142.34322
B55: Ms. Hema Ravichandar | C55: Non Executive | D55: 5.3 | E55: 17 | I55: Market Capitalization | J55: =J53*J54 -> 102202.43
...

Sheet Global, Indian And Industry 
B2: Global Outlook
B3: IMF, World Economic Outlook
B4: (Real GDP, annual percent change) | C4: 2025 | D4: 2026 (PROJECTIONS) | E4: 2027 (PROJECTIONS) | G4: Inflation
B5: World Output | C5: 3.4 | D5: 3.1 | E5: 3.2
B6: Advanced Economies | C6: 1.9 | D6: 1.8 | E6: 1.7
B7: United States | C7: 2.1 | D7: 2.3 | E7: 2.1
B8: Euro Area | C8: 1.4 | D8: 1.1 | E8: 1.2
B9: Other Advanced Economies | C9: 3 | D9: 2.6 | E9: 2.2
B10: Emerging Market and Developing Economies | C10: 4.4 | D10: 3.9 | E10: 4.2
B11: Emerging and Developing Asia | C11: 5.5 | D11: 4.9 | E11: 4.8
B12: China | C12: 5 | D12: 4.4 | E12: 4
B13: India | C13: 7.6 | D13: 6.5 | E13: 6.5
B14: Latin America and the Caribbean | C14: 2.4 | D14: 2.3 | E14: 2.7
B15: Emerging Market and Middle-Income Economies | C15: 4.4 | D15: 3.8 | E15: 4.1
B16: Low-Income Developing Countries | C16: 4.8 | D16: 4.8 | E16: 4.9
B18: India's Outlook & Key Risks &Opporunity
B19: PIB, Trading view
B20: Key Indicator | C20: 2025-2026 | E20: Macroeconomic Outlook
B21: Real GDP | C21: 0.078
B22: Nominal GDP | C22: 0.103
B23: GDP in Amount | C23: 4 Trillion USD
B24: Inflation Rate | C24: 0.0482
B25: Food Inflation | C25: 0.0595
B26: Unemployement Rate | C26: 0.05
B27: RBI Interest Rate | C27: 0.0525
B34: India Tourism Data
B35: Ministry of Tourism, Statistics 2025-2026 | C35: (in Lakhs)
B36: Year | C36: FTAs | D36: NRI Arrivals | E36: ITA | G36: % Break Down of Purpose of visit
B37: 2019 | C37: 109.3 | D37: 69.8 | E37: 179.1
B38: 2020 | C38: 27.4 | D38: 35.9 | E38: 63.3
B39: 2021 | C39: 15.2 | D39: 54.8 | E39: 70
B40: 2022 | C40: 64.4 | D40: 78.9 | E40: 143.3
B41: 2023 | C41: 95.1 | D41: 93.8 | E41: 188.9
B42: 2024 | C42: 99.5 | D42: 106.2 | E42: 205.7
B43: 2025 | C43: 91.5 | D43: 110.7 | E43: 202.2
B46: Year (Tourist Visit ) | C46: Domestic | D46: Foreign | G46: Forex Earning From Tourism
B47: 2019 | C47: 0.2526 | D47: 0.0886
B48: 2020 | C48: -0.7372 | D48: -0.7717
B49: 2021 | C49: 0.1105 | D49: -0.8529
B50: 2022 | C50: 1.5545 | D50: 7.1426
...

Sheet Financials>>

Sheet Historicial Financials
B1: #VALUE!
C2: ="Historical Financial Statement-"&'Data Sheet'!B1 -> Historical Financial Statement-INDIAN HOTELS CO LTD
B4: Years | C4: ='Data Sheet'!E16 -> 43921 | D4: ='Data Sheet'!F16 -> 44286 | E4: ='Data Sheet'!G16 -> 44651 | F4: ='Data Sheet'!H16 -> 45016 | G4: ='Data Sheet'!I16 -> 45382 | H4: ='Data Sheet'!J16 -> 45747 | I4: ='Data Sheet'!K16 -> 46112
A6: # | B6: Income Statements
B7: Sales | C7: =IFERROR('Data Sheet'!E17,0) -> 4463.14 | D7: =IFERROR('Data Sheet'!F17,0) -> 1575.16 | E7: =IFERROR('Data Sheet'!G17,0) -> 3056.22 | F7: =IFERROR('Data Sheet'!H17,0) -> 5809.91 | G7: =IFERROR('Data Sheet'!I17,0) -> 6768.75 | H7: =IFERROR('Data Sheet'!J17,0) -> 8334.54 | I7: =IFERROR('Data Sheet'!K17,0) -> 9689.22
B8: Sales Growth | C8: - | D8: =IFERROR(D7/C7-1,0) -> -0.64707358 | E8: =IFERROR(E7/D7-1,0) -> 0.94026004 | F8: =IFERROR(F7/E7-1,0) -> 0.90101171 | G8: =IFERROR(G7/F7-1,0) -> 0.16503526 | H8: =IFERROR(H7/G7-1,0) -> 0.23132632 | I8: =IFERROR(I7/H7-1,0) -> 0.16253806
B10: COGS | C10: =IFERROR(SUM('Data Sheet'!E18,'Data Sheet'!E20,'Data Sheet'!E21:E22)-1*'Data Sheet'!E19,0) -> 2947.21 | D10: =IFERROR(SUM('Data Sheet'!F18,'Data Sheet'!F20,'Data Sheet'!F21:F22)-1*'Data Sheet'!F19,0) -> 1572.93 | E10: =IFERROR(SUM('Data Sheet'!G18,'Data Sheet'!G20,'Data Sheet'!G21:G22)-1*'Data Sheet'!G19,0) -> 2209.74 | F10: =IFERROR(SUM('Data Sheet'!H18,'Data Sheet'!H20,'Data Sheet'!H21:H22)-1*'Data Sheet'!H19,0) -> 3410.17 | G10: =IFERROR(SUM('Data Sheet'!I18,'Data Sheet'!I20,'Data Sheet'!I21:I22)-1*'Data Sheet'!I19,0) -> 3889.96 | H10: =IFERROR(SUM('Data Sheet'!J18,'Data Sheet'!J20,'Data Sheet'!J21:J22)-1*'Data Sheet'!J19,0) -> 4396.82 | I10: =IFERROR(SUM('Data Sheet'!K18,'Data Sheet'!K20,'Data Sheet'!K21:K22)-1*'Data Sheet'!K19,0) -> 5082.69
B11: COGS % Sales | C11: =IFERROR(C10/C7,0) -> 0.66034451 | D11: =IFERROR(D10/D7,0) -> 0.99858427 | E11: =IFERROR(E10/E7,0) -> 0.72303041 | F11: =IFERROR(F10/F7,0) -> 0.58695746 | G11: =IFERROR(G10/G7,0) -> 0.574694 | H11: =IFERROR(H10/H7,0) -> 0.52754201 | I11: =IFERROR(I10/I7,0) -> 0.52457164
B13: Gross Profit | C13: =IFERROR(C7-C10,0) -> 1515.93 | D13: =IFERROR(D7-D10,0) -> 2.23 | E13: =IFERROR(E7-E10,0) -> 846.48 | F13: =IFERROR(F7-F10,0) -> 2399.74 | G13: =IFERROR(G7-G10,0) -> 2878.79 | H13: =IFERROR(H7-H10,0) -> 3937.72 | I13: =IFERROR(I7-I10,0) -> 4606.53
B14: Gross Margin | C14: =IFERROR(C13/C7,0) -> 0.33965549 | D14: =IFERROR(D13/D7,0) -> 0.0014157292 | E14: =IFERROR(E13/E7,0) -> 0.27696959 | F14: =IFERROR(F13/F7,0) -> 0.41304254 | G14: =IFERROR(G13/G7,0) -> 0.425306 | H14: =IFERROR(H13/H7,0) -> 0.47245799 | I14: =IFERROR(I13/I7,0) -> 0.47542836
B16: Selling & General Expenses | C16: =IFERROR(SUM('Data Sheet'!E23:E24),0) -> 548.4 | D16: =IFERROR(SUM('Data Sheet'!F23:F24),0) -> 363.99 | E16: =IFERROR(SUM('Data Sheet'!G23:G24),0) -> 441.73 | F16: =IFERROR(SUM('Data Sheet'!H23:H24),0) -> 595.18 | G16: =IFERROR(SUM('Data Sheet'!I23:I24),0) -> 719.28 | H16: =IFERROR(SUM('Data Sheet'!J23:J24),0) -> 1168.39 | I16: =IFERROR(SUM('Data Sheet'!K23:K24),0) -> 1410.73
B17: S&G Exp. | C17: =C16/C7 -> 0.12287313 | D17: =D16/D7 -> 0.23108129 | E17: =E16/E7 -> 0.14453475 | F17: =F16/F7 -> 0.10244221 | G17: =G16/G7 -> 0.10626482 | H17: =H16/H7 -> 0.1401865 | I17: =I16/I7 -> 0.14559789
B19: EBITDA | C19: =IFERROR(C13-C16,0) -> 967.53 | D19: =IFERROR(D13-D16,0) -> -361.76 | E19: =IFERROR(E13-E16,0) -> 404.75 | F19: =IFERROR(F13-F16,0) -> 1804.56 | G19: =IFERROR(G13-G16,0) -> 2159.51 | H19: =IFERROR(H13-H16,0) -> 2769.33 | I19: =IFERROR(I13-I16,0) -> 3195.8
B20: EBITDA Margin | C20: =C19/C7 -> 0.21678236 | D20: =D19/D7 -> -0.22966556 | E20: =E19/E7 -> 0.13243484 | F20: =F19/F7 -> 0.31060034 | G20: =G19/G7 -> 0.31904118 | H20: =H19/H7 -> 0.33227149 | I20: =I19/I7 -> 0.32983047
B22: Interest | C22: =IFERROR('Data Sheet'!E27,0) -> 341.12 | D22: =IFERROR('Data Sheet'!F27,0) -> 402.82 | E22: =IFERROR('Data Sheet'!G27,0) -> 427.66 | F22: =IFERROR('Data Sheet'!H27,0) -> 236.05 | G22: =IFERROR('Data Sheet'!I27,0) -> 220.22 | H22: =IFERROR('Data Sheet'!J27,0) -> 208.38 | I22: =IFERROR('Data Sheet'!K27,0) -> 221.35
B23: Interest % Sales | C23: =IFERROR(C22/C7,0) -> 0.076430495 | D23: =IFERROR(D22/D7,0) -> 0.25573275 | E23: =IFERROR(E22/E7,0) -> 0.13993103 | F23: =IFERROR(F22/F7,0) -> 0.040628857 | G23: =IFERROR(G22/G7,0) -> 0.032534811 | H23: =IFERROR(H22/H7,0) -> 0.02500198 | I23: =IFERROR(I22/I7,0) -> 0.022844976
B25: Depreciation | C25: =IFERROR('Data Sheet'!E26,0) -> 404.24 | D25: =IFERROR('Data Sheet'!F26,0) -> 409.63 | E25: =IFERROR('Data Sheet'!G26,0) -> 406.05 | F25: =IFERROR('Data Sheet'!H26,0) -> 416.06 | G25: =IFERROR('Data Sheet'!I26,0) -> 454.3 | H25: =IFERROR('Data Sheet'!J26,0) -> 518.16 | I25: =IFERROR('Data Sheet'!K26,0) -> 605.16
B26: Depreciation % Sales | C26: =IFERROR(C25/C7,0) -> 0.090573005 | D26: =IFERROR(D25/D7,0) -> 0.26005612 | E26: =IFERROR(E25/E7,0) -> 0.1328602 | F26: =IFERROR(F25/F7,0) -> 0.071612125 | G26: =IFERROR(G25/G7,0) -> 0.067117267 | H26: =IFERROR(H25/H7,0) -> 0.062170198 | I26: =IFERROR(I25/I7,0) -> 0.06245704
B28: EBT | C28: =IFERROR(C19-SUM(C22,C25),0) -> 222.17 | D28: =IFERROR(D19-SUM(D22,D25),0) -> -1174.21 | E28: =IFERROR(E19-SUM(E22,E25),0) -> -428.96 | F28: =IFERROR(F19-SUM(F22,F25),0) -> 1152.45 | G28: =IFERROR(G19-SUM(G22,G25),0) -> 1484.99 | H28: =IFERROR(H19-SUM(H22,H25),0) -> 2042.79 | I28: =IFERROR(I19-SUM(I22,I25),0) -> 2369.29
B29: EBT % Sales | C29: =IFERROR(C28/C7,0) -> 0.049778855 | D29: =IFERROR(D28/D7,0) -> -0.74545443 | E29: =IFERROR(E28/E7,0) -> -0.14035639 | F29: =IFERROR(F28/F7,0) -> 0.19835935 | G29: =IFERROR(G28/G7,0) -> 0.2193891 | H29: =IFERROR(H28/H7,0) -> 0.24509931 | I29: =IFERROR(I28/I7,0) -> 0.24452846
B31: Tax | C31: =IFERROR('Data Sheet'!E28-'Data Sheet'!E30,0) -> 41.12 | D31: =IFERROR('Data Sheet'!F28-'Data Sheet'!F30,0) -> -129.43 | E31: =IFERROR('Data Sheet'!G28-'Data Sheet'!G30,0) -> -10.46 | F31: =IFERROR('Data Sheet'!H28-'Data Sheet'!H30,0) -> 292.05 | G31: =IFERROR('Data Sheet'!I28-'Data Sheet'!I30,0) -> 406.46 | H31: =IFERROR('Data Sheet'!J28-'Data Sheet'!J30,0) -> 670.46 | I31: =IFERROR('Data Sheet'!K28-'Data Sheet'!K30,0) -> 841.48
B32: Effective Tax Rate | C32: =IFERROR(C31/C28,0) -> 0.18508349 | D32: =IFERROR(D31/D28,0) -> 0.1102273 | E32: =IFERROR(E31/E28,0) -> 0.024384558 | F32: =IFERROR(F31/F28,0) -> 0.25341663 | G32: =IFERROR(G31/G28,0) -> 0.27371228 | H32: =IFERROR(H31/H28,0) -> 0.32820799 | I32: =IFERROR(I31/I28,0) -> 0.35516125
B34: Net Profit | C34: =IFERROR(C28-C31,0) -> 181.05 | D34: =IFERROR(D28-D31,0) -> -1044.78 | E34: =IFERROR(E28-E31,0) -> -418.5 | F34: =IFERROR(F28-F31,0) -> 860.4 | G34: =IFERROR(G28-G31,0) -> 1078.53 | H34: =IFERROR(H28-H31,0) -> 1372.33 | I34: =IFERROR(I28-I31,0) -> 1527.81
B35: Net Margin | C35: =IFERROR(C34/C7,0) -> 0.040565611 | D35: =IFERROR(D34/D7,0) -> -0.663285 | E35: =IFERROR(E34/E7,0) -> -0.13693386 | F35: =IFERROR(F34/F7,0) -> 0.14809179 | G35: =IFERROR(G34/G7,0) -> 0.15933961 | H35: =IFERROR(H34/H7,0) -> 0.16465576 | I35: =IFERROR(I34/I7,0) -> 0.15768142
B37: No. of Equity Shares | C37: =IFERROR('Data Sheet'!E93,0) -> 132.14 | D37: =IFERROR('Data Sheet'!F93,0) -> 132.14 | E37: =IFERROR('Data Sheet'!G93,0) -> 142.04 | F37: =IFERROR('Data Sheet'!H93,0) -> 142.04 | G37: =IFERROR('Data Sheet'!I93,0) -> 142.34 | H37: =IFERROR('Data Sheet'!J93,0) -> 142.34 | I37: =IFERROR('Data Sheet'!K93,0) -> 142.34
B39: EPS | C39: =IFERROR(C34/C37,0) -> 1.3701377 | D39: =IFERROR(D34/D37,0) -> -7.9066142 | E39: =IFERROR(E34/E37,0) -> -2.9463531 | F39: =IFERROR(F34/F37,0) -> 6.0574486 | G39: =IFERROR(G34/G37,0) -> 7.5771392 | H39: =IFERROR(H34/H37,0) -> 9.6412112 | I39: =IFERROR(I34/I37,0) -> 10.733525
B40: EPS Growth | D40: =IFERROR(D39/C39-1,0) -> -6.7706711 | E40: =IFERROR(E39/D39-1,0) -> -0.6273559 | F40: =IFERROR(F39/E39-1,0) -> -3.055914 | G40: =IFERROR(G39/F39-1,0) -> 0.25087966 | H40: =IFERROR(H39/G39-1,0) -> 0.27240781 | I40: =IFERROR(I39/H39-1,0) -> 0.11329636
B42: Dividend per share | C42: ='Data Sheet'!E31/'Data Sheet'!E93 -> 0.4499773 | D42: ='Data Sheet'!F31/'Data Sheet'!F93 -> 0.35999697 | E42: ='Data Sheet'!G31/'Data Sheet'!G93 -> 0.40002816 | F42: ='Data Sheet'!H31/'Data Sheet'!H93 -> 1 | G42: ='Data Sheet'!I31/'Data Sheet'!I93 -> 1.7500351 | H42: ='Data Sheet'!J31/'Data Sheet'!J93 -> 2.2499649 | I42: ='Data Sheet'!K31/'Data Sheet'!K93 -> 3.2499649
B43: Dividend payout ratio | C43: ='Data Sheet'!E31/'Data Sheet'!E30 -> 0.16776706 | D43: ='Data Sheet'!F31/'Data Sheet'!F30 -> -0.066059352 | E43: ='Data Sheet'!G31/'Data Sheet'!G30 -> -0.22937187 | F43: ='Data Sheet'!H31/'Data Sheet'!H30 -> 0.14167307 | G43: ='Data Sheet'!I31/'Data Sheet'!I30 -> 0.19784444 | H43: ='Data Sheet'!J31/'Data Sheet'!J30 -> 0.16788723 | I43: ='Data Sheet'!K31/'Data Sheet'!K30 -> 0.2219365
B45: Retained Earnings | C45: =IFERROR(IF(C39>C42,1-C43,0),0) -> 0.83223294 | D45: =IFERROR(IF(D39>D42,1-D43,0),0) -> 0 | E45: =IFERROR(IF(E39>E42,1-E43,0),0) -> 0 | F45: =IFERROR(IF(F39>F42,1-F43,0),0) -> 0.85832693 | G45: =IFERROR(IF(G39>G42,1-G43,0),0) -> 0.80215556 | H45: =IFERROR(IF(H39>H42,1-H43,0),0) -> 0.83211277 | I45: =IFERROR(IF(I39>I42,1-I43,0),0) -> 0.7780635
A47: # | B47: Balance Sheet
B48: Equity Share Capital | C48: =IFERROR('Data Sheet'!E57,0) -> 118.93 | D48: =IFERROR('Data Sheet'!F57,0) -> 118.93 | E48: =IFERROR('Data Sheet'!G57,0) -> 142.04 | F48: =IFERROR('Data Sheet'!H57,0) -> 142.04 | G48: =IFERROR('Data Sheet'!I57,0) -> 142.34 | H48: =IFERROR('Data Sheet'!J57,0) -> 142.34 | I48: =IFERROR('Data Sheet'!K57,0) -> 142.34
B49: Reserves | C49: =IFERROR('Data Sheet'!E58,0) -> 4237.88 | D49: =IFERROR('Data Sheet'!F58,0) -> 3529.51 | E49: =IFERROR('Data Sheet'!G58,0) -> 6920.21 | F49: =IFERROR('Data Sheet'!H58,0) -> 7839.92 | G49: =IFERROR('Data Sheet'!I58,0) -> 9314.31 | H49: =IFERROR('Data Sheet'!J58,0) -> 11018.37 | I49: =IFERROR('Data Sheet'!K58,0) -> 12909.95
B50: Borrowings | C50: =IFERROR('Data Sheet'!E59,0) -> 4500.78 | D50: =IFERROR('Data Sheet'!F59,0) -> 5518.33 | E50: =IFERROR('Data Sheet'!G59,0) -> 3887.87 | F50: =IFERROR('Data Sheet'!H59,0) -> 3139.01 | G50: =IFERROR('Data Sheet'!I59,0) -> 2736.23 | H50: =IFERROR('Data Sheet'!J59,0) -> 3084.27 | I50: =IFERROR('Data Sheet'!K59,0) -> 2836.55
B51: Other Liabilities | C51: =IFERROR('Data Sheet'!E60,0) -> 2584.17 | D51: =IFERROR('Data Sheet'!F60,0) -> 2267.89 | E51: =IFERROR('Data Sheet'!G60,0) -> 2051.92 | F51: =IFERROR('Data Sheet'!H60,0) -> 2391.07 | G51: =IFERROR('Data Sheet'!I60,0) -> 2540.54 | H51: =IFERROR('Data Sheet'!J60,0) -> 3371 | I51: =IFERROR('Data Sheet'!K60,0) -> 4331.88
B52: Total Liabilities | C52: =IFERROR(SUM(C48:C51),0) -> 11441.76 | D52: =IFERROR(SUM(D48:D51),0) -> 11434.66 | E52: =IFERROR(SUM(E48:E51),0) -> 13002.04 | F52: =IFERROR(SUM(F48:F51),0) -> 13512.04 | G52: =IFERROR(SUM(G48:G51),0) -> 14733.42 | H52: =IFERROR(SUM(H48:H51),0) -> 17615.98 | I52: =IFERROR(SUM(I48:I51),0) -> 20220.72
B54: Fixed Assets Net Block | C54: =IFERROR('Data Sheet'!E62,0) -> 8058.85 | D54: =IFERROR('Data Sheet'!F62,0) -> 8437.7 | E54: =IFERROR('Data Sheet'!G62,0) -> 8415.34 | F54: =IFERROR('Data Sheet'!H62,0) -> 8818.53 | G54: =IFERROR('Data Sheet'!I62,0) -> 9311.34 | H54: =IFERROR('Data Sheet'!J62,0) -> 10918.18 | I54: =IFERROR('Data Sheet'!K62,0) -> 12210.06
B55: Capital Work in Progress | C55: =IFERROR('Data Sheet'!E63,0) -> 244.08 | D55: =IFERROR('Data Sheet'!F63,0) -> 164.99 | E55: =IFERROR('Data Sheet'!G63,0) -> 193.54 | F55: =IFERROR('Data Sheet'!H63,0) -> 332.05 | G55: =IFERROR('Data Sheet'!I63,0) -> 255.52 | H55: =IFERROR('Data Sheet'!J63,0) -> 632.57 | I55: =IFERROR('Data Sheet'!K63,0) -> 787.31
B56: Investments | C56: =IFERROR('Data Sheet'!E64,0) -> 1426.59 | D56: =IFERROR('Data Sheet'!F64,0) -> 1483.17 | E56: =IFERROR('Data Sheet'!G64,0) -> 1966.8 | F56: =IFERROR('Data Sheet'!H64,0) -> 1891.04 | G56: =IFERROR('Data Sheet'!I64,0) -> 2261.2 | H56: =IFERROR('Data Sheet'!J64,0) -> 2278.76 | I56: =IFERROR('Data Sheet'!K64,0) -> 3606.43
B57: Other Assets | C57: =IFERROR('Data Sheet'!E65-SUM('Data Sheet'!E67:E69),0) -> 1013.03 | D57: =IFERROR('Data Sheet'!F65-SUM('Data Sheet'!F67:F69),0) -> 882.45 | E57: =IFERROR('Data Sheet'!G65-SUM('Data Sheet'!G67:G69),0) -> 882.38 | F57: =IFERROR('Data Sheet'!H65-SUM('Data Sheet'!H67:H69),0) -> 861.33 | G57: =IFERROR('Data Sheet'!I65-SUM('Data Sheet'!I67:I69),0) -> 826.96 | H57: =IFERROR('Data Sheet'!J65-SUM('Data Sheet'!J67:J69),0) -> 818.56 | I57: =IFERROR('Data Sheet'!K65-SUM('Data Sheet'!K67:K69),0) -> 909.18
...

Sheet Common Size Statement
A2: # | B2: ="Common Size P&L Statement-"&'Data Sheet'!B1 -> Common Size P&L Statement-INDIAN HOTELS CO LTD
B4: Particular | C4: ='Data Sheet'!E16 -> 43921 | D4: ='Data Sheet'!F16 -> 44286 | E4: ='Data Sheet'!G16 -> 44651 | F4: ='Data Sheet'!H16 -> 45016 | G4: ='Data Sheet'!I16 -> 45382 | H4: ='Data Sheet'!J16 -> 45747 | I4: ='Data Sheet'!K16 -> 46112
B6: Sales | C6: ='Data Sheet'!E17/'Data Sheet'!E$17 -> 1 | D6: ='Data Sheet'!F17/'Data Sheet'!F$17 -> 1 | E6: ='Data Sheet'!G17/'Data Sheet'!G$17 -> 1 | F6: ='Data Sheet'!H17/'Data Sheet'!H$17 -> 1 | G6: ='Data Sheet'!I17/'Data Sheet'!I$17 -> 1 | H6: ='Data Sheet'!J17/'Data Sheet'!J$17 -> 1 | I6: ='Data Sheet'!K17/'Data Sheet'!K$17 -> 1
B7: Raw Material Cost | C7: ='Data Sheet'!E18/'Data Sheet'!E$17 -> 0.083026748 | D7: ='Data Sheet'!F18/'Data Sheet'!F$17 -> 0.09130501 | E7: ='Data Sheet'!G18/'Data Sheet'!G$17 -> 0.084166061 | F7: ='Data Sheet'!H18/'Data Sheet'!H$17 -> 0.081393688 | G7: ='Data Sheet'!I18/'Data Sheet'!I$17 -> 0.07694626 | H7: ='Data Sheet'!J18/'Data Sheet'!J$17 -> 0.092836557 | I7: ='Data Sheet'!K18/'Data Sheet'!K$17 -> 0.098138963
B8: Change in Inventory | C8: ='Data Sheet'!E19/'Data Sheet'!E$17 -> 0 | D8: ='Data Sheet'!F19/'Data Sheet'!F$17 -> 0 | E8: ='Data Sheet'!G19/'Data Sheet'!G$17 -> 0 | F8: ='Data Sheet'!H19/'Data Sheet'!H$17 -> 0 | G8: ='Data Sheet'!I19/'Data Sheet'!I$17 -> 0 | H8: ='Data Sheet'!J19/'Data Sheet'!J$17 -> 0 | I8: ='Data Sheet'!K19/'Data Sheet'!K$17 -> 0
B9: Power and Fuel | C9: ='Data Sheet'!E20/'Data Sheet'!E$17 -> 0.060466398 | D9: ='Data Sheet'!F20/'Data Sheet'!F$17 -> 0.10973488 | E9: ='Data Sheet'!G20/'Data Sheet'!G$17 -> 0.073551642 | F9: ='Data Sheet'!H20/'Data Sheet'!H$17 -> 0.052167762 | G9: ='Data Sheet'!I20/'Data Sheet'!I$17 -> 0.045649492 | H9: ='Data Sheet'!J20/'Data Sheet'!J$17 -> 0.043272934 | I9: ='Data Sheet'!K20/'Data Sheet'!K$17 -> 0.038919542
B10: Other Mfr. Exp | C10: ='Data Sheet'!E21/'Data Sheet'!E$17 -> 0.18106311 | D10: ='Data Sheet'!F21/'Data Sheet'!F$17 -> 0.22863074 | E10: ='Data Sheet'!G21/'Data Sheet'!G$17 -> 0.18791841 | F10: ='Data Sheet'!H21/'Data Sheet'!H$17 -> 0.17995115 | G10: ='Data Sheet'!I21/'Data Sheet'!I$17 -> 0.18453333 | H10: ='Data Sheet'!J21/'Data Sheet'!J$17 -> 0.13266959 | I10: ='Data Sheet'!K21/'Data Sheet'!K$17 -> 0.13034589
B11: Employee Cost | C11: ='Data Sheet'!E22/'Data Sheet'!E$17 -> 0.33578826 | D11: ='Data Sheet'!F22/'Data Sheet'!F$17 -> 0.56891363 | E11: ='Data Sheet'!G22/'Data Sheet'!G$17 -> 0.3773943 | F11: ='Data Sheet'!H22/'Data Sheet'!H$17 -> 0.27344486 | G11: ='Data Sheet'!I22/'Data Sheet'!I$17 -> 0.26756491 | H11: ='Data Sheet'!J22/'Data Sheet'!J$17 -> 0.25876293 | I11: ='Data Sheet'!K22/'Data Sheet'!K$17 -> 0.25716724
B12: Selling and admin | C12: ='Data Sheet'!E23/'Data Sheet'!E$17 -> 0.095495548 | D12: ='Data Sheet'!F23/'Data Sheet'!F$17 -> 0.16739887 | E12: ='Data Sheet'!G23/'Data Sheet'!G$17 -> 0.10831027 | F12: ='Data Sheet'!H23/'Data Sheet'!H$17 -> 0.081402294 | G12: ='Data Sheet'!I23/'Data Sheet'!I$17 -> 0.084067221 | H12: ='Data Sheet'!J23/'Data Sheet'!J$17 -> 0.11861722 | I12: ='Data Sheet'!K23/'Data Sheet'!K$17 -> 0.12122751
B13: Other Expenses | C13: ='Data Sheet'!E24/'Data Sheet'!E$17 -> 0.027377586 | D13: ='Data Sheet'!F24/'Data Sheet'!F$17 -> 0.06368242 | E13: ='Data Sheet'!G24/'Data Sheet'!G$17 -> 0.036224486 | F13: ='Data Sheet'!H24/'Data Sheet'!H$17 -> 0.021039913 | G13: ='Data Sheet'!I24/'Data Sheet'!I$17 -> 0.022197599 | H13: ='Data Sheet'!J24/'Data Sheet'!J$17 -> 0.021569277 | I13: ='Data Sheet'!K24/'Data Sheet'!K$17 -> 0.024370383
B14: Other Income | C14: ='Data Sheet'!E25/'Data Sheet'!E$17 -> 0.038844849 | D14: ='Data Sheet'!F25/'Data Sheet'!F$17 -> 0.20611874 | E14: ='Data Sheet'!G25/'Data Sheet'!G$17 -> 0.055879485 | F14: ='Data Sheet'!H25/'Data Sheet'!H$17 -> 0.024473701 | G14: ='Data Sheet'!I25/'Data Sheet'!I$17 -> 0.026672576 | H14: ='Data Sheet'!J25/'Data Sheet'!J$17 -> 0.064221901 | I14: ='Data Sheet'!K25/'Data Sheet'!K$17 -> 0.057442188
B15: Depreciation | C15: ='Data Sheet'!E26/'Data Sheet'!E$17 -> 0.090573005 | D15: ='Data Sheet'!F26/'Data Sheet'!F$17 -> 0.26005612 | E15: ='Data Sheet'!G26/'Data Sheet'!G$17 -> 0.1328602 | F15: ='Data Sheet'!H26/'Data Sheet'!H$17 -> 0.071612125 | G15: ='Data Sheet'!I26/'Data Sheet'!I$17 -> 0.067117267 | H15: ='Data Sheet'!J26/'Data Sheet'!J$17 -> 0.062170198 | I15: ='Data Sheet'!K26/'Data Sheet'!K$17 -> 0.06245704
B16: Interest | C16: ='Data Sheet'!E27/'Data Sheet'!E$17 -> 0.076430495 | D16: ='Data Sheet'!F27/'Data Sheet'!F$17 -> 0.25573275 | E16: ='Data Sheet'!G27/'Data Sheet'!G$17 -> 0.13993103 | F16: ='Data Sheet'!H27/'Data Sheet'!H$17 -> 0.040628857 | G16: ='Data Sheet'!I27/'Data Sheet'!I$17 -> 0.032534811 | H16: ='Data Sheet'!J27/'Data Sheet'!J$17 -> 0.02500198 | I16: ='Data Sheet'!K27/'Data Sheet'!K$17 -> 0.022844976
B17: Profit before tax | C17: ='Data Sheet'!E28/'Data Sheet'!E$17 -> 0.088623704 | D17: ='Data Sheet'!F28/'Data Sheet'!F$17 -> -0.53933569 | E17: ='Data Sheet'!G28/'Data Sheet'!G$17 -> -0.084476903 | F17: ='Data Sheet'!H28/'Data Sheet'!H$17 -> 0.22283306 | G17: ='Data Sheet'!I28/'Data Sheet'!I$17 -> 0.24606168 | H17: ='Data Sheet'!J28/'Data Sheet'!J$17 -> 0.30932121 | I17: ='Data Sheet'!K28/'Data Sheet'!K$17 -> 0.30197064
... B20: Dividend Amount | C20: ='Data Sheet'!E31/'Data Sheet'!E$17 -> 0.013322459 | D20: ='Data Sheet'!F31/'Data Sheet'!F$17 -> 0.030200107 | E20: ='Data Sheet'!G31/'Data Sheet'!G$17 -> 0.018591594 | F20: ='Data Sheet'!H31/'Data Sheet'!H$17 -> 0.024447883 | G20: ='Data Sheet'!I31/'Data Sheet'!I$17 -> 0.036801477 | H20: ='Data Sheet'!J31/'Data Sheet'!J$17 -> 0.038425636 | I20: ='Data Sheet'!K31/'Data Sheet'!K$17 -> 0.047743781
B21: EBITDA | C21: ='Historicial Financials'!C19/'Historicial Financials'!C$7 -> 0.21678236 | D21: ='Historicial Financials'!D19/'Historicial Financials'!D$7 -> -0.22966556 | E21: ='Historicial Financials'!E19/'Historicial Financials'!E$7 -> 0.13243484 | F21: ='Historicial Financials'!F19/'Historicial Financials'!F$7 -> 0.31060034 | G21: ='Historicial Financials'!G19/'Historicial Financials'!G$7 -> 0.31904118 | H21: ='Historicial Financials'!H19/'Historicial Financials'!H$7 -> 0.33227149 | I21: ='Historicial Financials'!I19/'Historicial Financials'!I$7 -> 0.32983047
A23: # | B23: ="Common Size Balance sheet Statement-"&'Data Sheet'!B1 -> Common Size Balance sheet Statement-INDIAN HOTELS CO LTD
B25: Particular | C25: ='Data Sheet'!E16 -> 43921 | D25: ='Data Sheet'!F16 -> 44286 | E25: ='Data Sheet'!G16 -> 44651 | F25: ='Data Sheet'!H16 -> 45016 | G25: ='Data Sheet'!I16 -> 45382 | H25: ='Data Sheet'!J16 -> 45747 | I25: ='Data Sheet'!K16 -> 46112
B27: Total Liabilities | C27: ='Data Sheet'!E61/'Data Sheet'!E$61 -> 1 | D27: ='Data Sheet'!F61/'Data Sheet'!F$61 -> 1 | E27: ='Data Sheet'!G61/'Data Sheet'!G$61 -> 1 | F27: ='Data Sheet'!H61/'Data Sheet'!H$61 -> 1 | G27: ='Data Sheet'!I61/'Data Sheet'!I$61 -> 1 | H27: ='Data Sheet'!J61/'Data Sheet'!J$61 -> 1 | I27: ='Data Sheet'!K61/'Data Sheet'!K$61 -> 1
B28: Equity Share Capital | C28: ='Data Sheet'!E57/'Data Sheet'!E$61 -> 0.01039438 | D28: ='Data Sheet'!F57/'Data Sheet'!F$61 -> 0.010400834 | E28: ='Data Sheet'!G57/'Data Sheet'!G$61 -> 0.01092444 | F28: ='Data Sheet'!H57/'Data Sheet'!H$61 -> 0.010512106 | G28: ='Data Sheet'!I57/'Data Sheet'!I$61 -> 0.0096610291 | H28: ='Data Sheet'!J57/'Data Sheet'!J$61 -> 0.0080801636 | I28: ='Data Sheet'!K57/'Data Sheet'!K$61 -> 0.0070393141
B29: Reserves | C29: ='Data Sheet'!E58/'Data Sheet'!E$61 -> 0.37038707 | D29: ='Data Sheet'!F58/'Data Sheet'!F$61 -> 0.30866768 | E29: ='Data Sheet'!G58/'Data Sheet'!G$61 -> 0.53224033 | F29: ='Data Sheet'!H58/'Data Sheet'!H$61 -> 0.58021735 | G29: ='Data Sheet'!I58/'Data Sheet'!I$61 -> 0.63218927 | H29: ='Data Sheet'!J58/'Data Sheet'!J$61 -> 0.62547585 | I29: ='Data Sheet'!K58/'Data Sheet'!K$61 -> 0.63845155
B30: Borrowings | C30: ='Data Sheet'!E59/'Data Sheet'!E$61 -> 0.39336431 | D30: ='Data Sheet'!F59/'Data Sheet'!F$61 -> 0.48259677 | E30: ='Data Sheet'!G59/'Data Sheet'!G$61 -> 0.29902 | F30: ='Data Sheet'!H59/'Data Sheet'!H$61 -> 0.23231207 | G30: ='Data Sheet'!I59/'Data Sheet'!I$61 -> 0.18571588 | H30: ='Data Sheet'!J59/'Data Sheet'!J$61 -> 0.17508365 | I30: ='Data Sheet'!K59/'Data Sheet'!K$61 -> 0.14027938
B31: Other Liabilities | C31: ='Data Sheet'!E60/'Data Sheet'!E$61 -> 0.22585424 | D31: ='Data Sheet'!F60/'Data Sheet'!F$61 -> 0.19833471 | E31: ='Data Sheet'!G60/'Data Sheet'!G$61 -> 0.15781524 | F31: ='Data Sheet'!H60/'Data Sheet'!H$61 -> 0.17695848 | G31: ='Data Sheet'!I60/'Data Sheet'!I$61 -> 0.17243383 | H31: ='Data Sheet'!J60/'Data Sheet'!J$61 -> 0.19136034 | I31: ='Data Sheet'!K60/'Data Sheet'!K$61 -> 0.21422976
B33: Total Assets | C33: ='Data Sheet'!E61/'Data Sheet'!E$61 -> 1 | D33: ='Data Sheet'!F61/'Data Sheet'!F$61 -> 1 | E33: ='Data Sheet'!G61/'Data Sheet'!G$61 -> 1 | F33: ='Data Sheet'!H61/'Data Sheet'!H$61 -> 1 | G33: ='Data Sheet'!I61/'Data Sheet'!I$61 -> 1 | H33: ='Data Sheet'!J61/'Data Sheet'!J$61 -> 1 | I33: ='Data Sheet'!K61/'Data Sheet'!K$61 -> 1
B34: Fixed Assets Net Block | C34: ='Data Sheet'!E62/'Data Sheet'!E$61 -> 0.70433657 | D34: ='Data Sheet'!F62/'Data Sheet'!F$61 -> 0.73790563 | E34: ='Data Sheet'!G62/'Data Sheet'!G$61 -> 0.64723228 | F34: ='Data Sheet'!H62/'Data Sheet'!H$61 -> 0.65264238 | G34: ='Data Sheet'!I62/'Data Sheet'!I$61 -> 0.63198769 | H34: ='Data Sheet'!J62/'Data Sheet'!J$61 -> 0.6197884 | I34: ='Data Sheet'!K62/'Data Sheet'!K$61 -> 0.60383903
B35: Capital Work in Progress | C35: ='Data Sheet'!E63/'Data Sheet'!E$61 -> 0.021332382 | D35: ='Data Sheet'!F63/'Data Sheet'!F$61 -> 0.014428938 | E35: ='Data Sheet'!G63/'Data Sheet'!G$61 -> 0.014885356 | F35: ='Data Sheet'!H63/'Data Sheet'!H$61 -> 0.02457438 | G35: ='Data Sheet'!I63/'Data Sheet'!I$61 -> 0.017342884 | H35: ='Data Sheet'!J63/'Data Sheet'!J$61 -> 0.035908874 | I35: ='Data Sheet'!K63/'Data Sheet'!K$61 -> 0.038935804
B36: Investments | C36: ='Data Sheet'!E64/'Data Sheet'!E$61 -> 0.12468274 | D36: ='Data Sheet'!F64/'Data Sheet'!F$61 -> 0.12970827 | E36: ='Data Sheet'!G64/'Data Sheet'!G$61 -> 0.15126857 | F36: ='Data Sheet'!H64/'Data Sheet'!H$61 -> 0.13995222 | G36: ='Data Sheet'!I64/'Data Sheet'!I$61 -> 0.15347421 | H36: ='Data Sheet'!J64/'Data Sheet'!J$61 -> 0.12935755 | I36: ='Data Sheet'!K64/'Data Sheet'!K$61 -> 0.17835319
B37: Other Assets | C37: ='Data Sheet'!E65/'Data Sheet'!E$61 -> 0.14964831 | D37: ='Data Sheet'!F65/'Data Sheet'!F$61 -> 0.11795716 | E37: ='Data Sheet'!G65/'Data Sheet'!G$61 -> 0.18661379 | F37: ='Data Sheet'!H65/'Data Sheet'!H$61 -> 0.18283102 | G37: ='Data Sheet'!I65/'Data Sheet'!I$61 -> 0.19719522 | H37: ='Data Sheet'!J65/'Data Sheet'!J$61 -> 0.21494518 | I37: ='Data Sheet'!K65/'Data Sheet'!K$61 -> 0.17887197
B38: Receivables | C38: ='Data Sheet'!E67/'Data Sheet'!E$61 -> 0.025347499 | D38: ='Data Sheet'!F67/'Data Sheet'!F$61 -> 0.019225757 | E38: ='Data Sheet'!G67/'Data Sheet'!G$61 -> 0.019638457 | F38: ='Data Sheet'!H67/'Data Sheet'!H$61 -> 0.033040903 | G38: ='Data Sheet'!I67/'Data Sheet'!I$61 -> 0.032338724 | H38: ='Data Sheet'!J67/'Data Sheet'!J$61 -> 0.036948271 | I38: ='Data Sheet'!K67/'Data Sheet'!K$61 -> 0.035944319
B39: Inventory | C39: ='Data Sheet'!E68/'Data Sheet'!E$61 -> 0.0081814336 | D39: ='Data Sheet'!F68/'Data Sheet'!F$61 -> 0.0081226726 | E39: ='Data Sheet'!G68/'Data Sheet'!G$61 -> 0.0077549369 | F39: ='Data Sheet'!H68/'Data Sheet'!H$61 -> 0.0080824213 | G39: ='Data Sheet'!I68/'Data Sheet'!I$61 -> 0.0079031209 | H39: ='Data Sheet'!J68/'Data Sheet'!J$61 -> 0.0076901768 | I39: ='Data Sheet'!K68/'Data Sheet'!K$61 -> 0.0074047808
B40: Cash & Bank | C40: ='Data Sheet'!E69/'Data Sheet'!E$61 -> 0.027581421 | D40: ='Data Sheet'!F69/'Data Sheet'!F$61 -> 0.013435467 | E40: ='Data Sheet'!G69/'Data Sheet'!G$61 -> 0.091355664 | F40: ='Data Sheet'!H69/'Data Sheet'!H$61 -> 0.077962321 | G40: ='Data Sheet'!I69/'Data Sheet'!I$61 -> 0.1008252 | H40: ='Data Sheet'!J69/'Data Sheet'!J$61 -> 0.12383983 | I40: ='Data Sheet'!K69/'Data Sheet'!K$61 -> 0.090560079

Sheet Ratio Analysis
B2: ="Ratio Analysis-"&'Data Sheet'!B1 -> Ratio Analysis-INDIAN HOTELS CO LTD
B4: Years | C4: ='Historicial Financials'!C4 -> 43921 | D4: ='Historicial Financials'!D4 -> 44286 | E4: ='Historicial Financials'!E4 -> 44651 | F4: ='Historicial Financials'!F4 -> 45016 | G4: ='Historicial Financials'!G4 -> 45382 | H4: ='Historicial Financials'!H4 -> 45747 | I4: ='Historicial Financials'!I4 -> 46112 | J4: Trend | K4: Mean | L4: Median
B6: SalesGrowth | D6: =IFERROR('Historicial Financials'!D8,0) -> -0.64707358 | E6: =IFERROR('Historicial Financials'!E8,0) -> 0.94026004 | F6: =IFERROR('Historicial Financials'!F8,0) -> 0.90101171 | G6: =IFERROR('Historicial Financials'!G8,0) -> 0.16503526 | H6: =IFERROR('Historicial Financials'!H8,0) -> 0.23132632 | I6: =IFERROR('Historicial Financials'!I8,0) -> 0.16253806 | K6: =IFERROR(AVERAGE(D6:I6),0) -> 0.29218297 | L6: =IFERROR(MEDIAN(D6:I6),0) -> 0.19818079
B7: EBITDA Growth | D7: =IFERROR('Historicial Financials'!D19/'Historicial Financials'!C19-1,0) -> -1.3739006 | E7: =IFERROR('Historicial Financials'!E19/'Historicial Financials'!D19-1,0) -> -2.1188357 | F7: =IFERROR('Historicial Financials'!F19/'Historicial Financials'!E19-1,0) -> 3.4584558 | G7: =IFERROR('Historicial Financials'!G19/'Historicial Financials'!F19-1,0) -> 0.19669615 | H7: =IFERROR('Historicial Financials'!H19/'Historicial Financials'!G19-1,0) -> 0.28238813 | I7: =IFERROR('Historicial Financials'!I19/'Historicial Financials'!H19-1,0) -> 0.15399754 | K7: =IFERROR(AVERAGE(D7:I7),0) -> 0.099800236 | L7: =IFERROR(MEDIAN(D7:I7),0) -> 0.17534684
B8: EBT Growth | D8: =IFERROR('Historicial Financials'!D28/'Historicial Financials'!C28-1,0) -> -6.285187 | E8: =IFERROR('Historicial Financials'!E28/'Historicial Financials'!D28-1,0) -> -0.63468204 | F8: =IFERROR('Historicial Financials'!F28/'Historicial Financials'!E28-1,0) -> -3.6866141 | G8: =IFERROR('Historicial Financials'!G28/'Historicial Financials'!F28-1,0) -> 0.28855048 | H8: =IFERROR('Historicial Financials'!H28/'Historicial Financials'!G28-1,0) -> 0.37562543 | I8: =IFERROR('Historicial Financials'!I28/'Historicial Financials'!H28-1,0) -> 0.15983043 | K8: =IFERROR(AVERAGE(D8:I8),0) -> -1.6304128 | L8: =IFERROR(MEDIAN(D8:I8),0) -> -0.23742581
B9: Net Profit Growth | D9: =IFERROR('Historicial Financials'!D34/'Historicial Financials'!C34-1,0) -> -6.7706711 | E9: =IFERROR('Historicial Financials'!E34/'Historicial Financials'!D34-1,0) -> -0.5994372 | F9: =IFERROR('Historicial Financials'!F34/'Historicial Financials'!E34-1,0) -> -3.055914 | G9: =IFERROR('Historicial Financials'!G34/'Historicial Financials'!F34-1,0) -> 0.25352162 | H9: =IFERROR('Historicial Financials'!H34/'Historicial Financials'!G34-1,0) -> 0.27240781 | I9: =IFERROR('Historicial Financials'!I34/'Historicial Financials'!H34-1,0) -> 0.11329636 | K9: =IFERROR(AVERAGE(D9:I9),0) -> -1.6311327 | L9: =IFERROR(MEDIAN(D9:I9),0) -> -0.24307042
B10: Dividend Growth | D10: =IFERROR('Historicial Financials'!D42/'Historicial Financials'!C42-1,0) -> -0.19996636 | E10: =IFERROR('Historicial Financials'!E42/'Historicial Financials'!D42-1,0) -> 0.11119868 | F10: =IFERROR('Historicial Financials'!F42/'Historicial Financials'!E42-1,0) -> 1.499824 | G10: =IFERROR('Historicial Financials'!G42/'Historicial Financials'!F42-1,0) -> 0.75003513 | H10: =IFERROR('Historicial Financials'!H42/'Historicial Financials'!G42-1,0) -> 0.28566841 | I10: =IFERROR('Historicial Financials'!I42/'Historicial Financials'!H42-1,0) -> 0.44445138 | K10: =IFERROR(AVERAGE(D10:I10),0) -> 0.48186854 | L10: =IFERROR(MEDIAN(D10:I10),0) -> 0.36505989
B12: Gross Margin | C12: =IFERROR('Historicial Financials'!C14,0) -> 0.33965549 | D12: =IFERROR('Historicial Financials'!D14,0) -> 0.0014157292 | E12: =IFERROR('Historicial Financials'!E14,0) -> 0.27696959 | F12: =IFERROR('Historicial Financials'!F14,0) -> 0.41304254 | G12: =IFERROR('Historicial Financials'!G14,0) -> 0.425306 | H12: =IFERROR('Historicial Financials'!H14,0) -> 0.47245799 | I12: =IFERROR('Historicial Financials'!I14,0) -> 0.47542836 | K12: =IFERROR(AVERAGE(C12:I12),0) -> 0.34346796 | L12: =IFERROR(MEDIAN(D12:I12),0) -> 0.41917427
B13: Operating Margin | C13: =IFERROR('Historicial Financials'!C20,0) -> 0.21678236 | D13: =IFERROR('Historicial Financials'!D20,0) -> -0.22966556 | E13: =IFERROR('Historicial Financials'!E20,0) -> 0.13243484 | F13: =IFERROR('Historicial Financials'!F20,0) -> 0.31060034 | G13: =IFERROR('Historicial Financials'!G20,0) -> 0.31904118 | H13: =IFERROR('Historicial Financials'!H20,0) -> 0.33227149 | I13: =IFERROR('Historicial Financials'!I20,0) -> 0.32983047 | K13: =IFERROR(AVERAGE(C13:I13),0) -> 0.20161359 | L13: =IFERROR(MEDIAN(D13:I13),0) -> 0.31482076
B14: EBITDA Margin | C14: =IFERROR('Historicial Financials'!C20,0) -> 0.21678236 | D14: =IFERROR('Historicial Financials'!D20,0) -> -0.22966556 | E14: =IFERROR('Historicial Financials'!E20,0) -> 0.13243484 | F14: =IFERROR('Historicial Financials'!F20,0) -> 0.31060034 | G14: =IFERROR('Historicial Financials'!G20,0) -> 0.31904118 | H14: =IFERROR('Historicial Financials'!H20,0) -> 0.33227149 | I14: =IFERROR('Historicial Financials'!I20,0) -> 0.32983047 | K14: =IFERROR(AVERAGE(C14:I14),0) -> 0.20161359 | L14: =IFERROR(MEDIAN(D14:I14),0) -> 0.31482076
B15: EBIT Margin | C15: =IFERROR(('Historicial Financials'!C19-'Historicial Financials'!C25)/'Historicial Financials'!C7,0) -> 0.12620935 | D15: =IFERROR(('Historicial Financials'!D19-'Historicial Financials'!D25)/'Historicial Financials'!D7,0) -> -0.48972168 | E15: =IFERROR(('Historicial Financials'!E19-'Historicial Financials'!E25)/'Historicial Financials'!E7,0) -> -0.00042536205 | F15: =IFERROR(('Historicial Financials'!F19-'Historicial Financials'!F25)/'Historicial Financials'!F7,0) -> 0.23898821 | G15: =IFERROR(('Historicial Financials'!G19-'Historicial Financials'!G25)/'Historicial Financials'!G7,0) -> 0.25192392 | H15: =IFERROR(('Historicial Financials'!H19-'Historicial Financials'!H25)/'Historicial Financials'!H7,0) -> 0.27010129 | I15: =IFERROR(('Historicial Financials'!I19-'Historicial Financials'!I25)/'Historicial Financials'!I7,0) -> 0.26737343 | K15: =IFERROR(AVERAGE(C15:I15),0) -> 0.094921308 | L15: =IFERROR(MEDIAN(D15:I15),0) -> 0.24545606
B16: EBT Margin | C16: =IFERROR('Historicial Financials'!C29,0) -> 0.049778855 | D16: =IFERROR('Historicial Financials'!D29,0) -> -0.74545443 | E16: =IFERROR('Historicial Financials'!E29,0) -> -0.14035639 | F16: =IFERROR('Historicial Financials'!F29,0) -> 0.19835935 | G16: =IFERROR('Historicial Financials'!G29,0) -> 0.2193891 | H16: =IFERROR('Historicial Financials'!H29,0) -> 0.24509931 | I16: =IFERROR('Historicial Financials'!I29,0) -> 0.24452846 | K16: =IFERROR(AVERAGE(C16:I16),0) -> 0.010192037 | L16: =IFERROR(MEDIAN(D16:I16),0) -> 0.20887423
B17: Net Profit Margin | C17: =IFERROR('Historicial Financials'!C35,0) -> 0.040565611 | D17: =IFERROR('Historicial Financials'!D35,0) -> -0.663285 | E17: =IFERROR('Historicial Financials'!E35,0) -> -0.13693386 | F17: =IFERROR('Historicial Financials'!F35,0) -> 0.14809179 | G17: =IFERROR('Historicial Financials'!G35,0) -> 0.15933961 | H17: =IFERROR('Historicial Financials'!H35,0) -> 0.16465576 | I17: =IFERROR('Historicial Financials'!I35,0) -> 0.15768142 | K17: =IFERROR(AVERAGE(C17:I17),0) -> -0.018554951 | L17: =IFERROR(MEDIAN(D17:I17),0) -> 0.15288661
B19: SalesExpenses%Sales | C19: =IFERROR('Historicial Financials'!C17,0) -> 0.12287313 | D19: =IFERROR('Historicial Financials'!D17,0) -> 0.23108129 | E19: =IFERROR('Historicial Financials'!E17,0) -> 0.14453475 | F19: =IFERROR('Historicial Financials'!F17,0) -> 0.10244221 | G19: =IFERROR('Historicial Financials'!G17,0) -> 0.10626482 | H19: =IFERROR('Historicial Financials'!H17,0) -> 0.1401865 | I19: =IFERROR('Historicial Financials'!I17,0) -> 0.14559789 | K19: =IFERROR(AVERAGE(C19:I19),0) -> 0.14185437 | L19: =IFERROR(MEDIAN(D19:I19),0) -> 0.14236063
B20: Depreciation%Sales | C20: =IFERROR('Historicial Financials'!C26,0) -> 0.090573005 | D20: =IFERROR('Historicial Financials'!D26,0) -> 0.26005612 | E20: =IFERROR('Historicial Financials'!E26,0) -> 0.1328602 | F20: =IFERROR('Historicial Financials'!F26,0) -> 0.071612125 | G20: =IFERROR('Historicial Financials'!G26,0) -> 0.067117267 | H20: =IFERROR('Historicial Financials'!H26,0) -> 0.062170198 | I20: =IFERROR('Historicial Financials'!I26,0) -> 0.06245704 | K20: =IFERROR(AVERAGE(C20:I20),0) -> 0.10669228 | L20: =IFERROR(MEDIAN(D20:I20),0) -> 0.069364696
B21: OperatingIncome%Sales | C21: =IFERROR(C15,0) -> 0.12620935 | D21: =IFERROR(D15,0) -> -0.48972168 | E21: =IFERROR(E15,0) -> -0.00042536205 | F21: =IFERROR(F15,0) -> 0.23898821 | G21: =IFERROR(G15,0) -> 0.25192392 | H21: =IFERROR(H15,0) -> 0.27010129 | I21: =IFERROR(I15,0) -> 0.26737343 | K21: =IFERROR(AVERAGE(C21:I21),0) -> 0.094921308 | L21: =IFERROR(MEDIAN(D21:I21),0) -> 0.24545606
B23: Return on Capital Employed | C23: =IFERROR(('Historicial Financials'!C19-'Historicial Financials'!C25)/SUM('Historicial Financials'!C48:C50),0) -> 0.063594048 | D23: =IFERROR(('Historicial Financials'!D19-'Historicial Financials'!D25)/SUM('Historicial Financials'!D48:D50),0) -> -0.084150688 | E23: =IFERROR(('Historicial Financials'!E19-'Historicial Financials'!E25)/SUM('Historicial Financials'!E48:E50),0) -> -0.00011872016 | F23: =IFERROR(('Historicial Financials'!F19-'Historicial Financials'!F25)/SUM('Historicial Financials'!F48:F50),0) -> 0.12485422 | G23: =IFERROR(('Historicial Financials'!G19-'Historicial Financials'!G25)/SUM('Historicial Financials'!G48:G50),0) -> 0.13985293 | H23: =IFERROR(('Historicial Financials'!H19-'Historicial Financials'!H25)/SUM('Historicial Financials'!H48:H50),0) -> 0.15803251 | I23: =IFERROR(('Historicial Financials'!I19-'Historicial Financials'!I25)/SUM('Historicial Financials'!I48:I50),0) -> 0.16304777 | K23: =IFERROR(AVERAGE(C23:I23),0) -> 0.080730296 | L23: =IFERROR(MEDIAN(D23:I23),0) -> 0.13235357
B24: Retained Earnings% | C24: =IFERROR('Historicial Financials'!C45,0) -> 0.83223294 | D24: =IFERROR('Historicial Financials'!D45,0) -> 0 | E24: =IFERROR('Historicial Financials'!E45,0) -> 0 | F24: =IFERROR('Historicial Financials'!F45,0) -> 0.85832693 | G24: =IFERROR('Historicial Financials'!G45,0) -> 0.80215556 | H24: =IFERROR('Historicial Financials'!H45,0) -> 0.83211277 | I24: =IFERROR('Historicial Financials'!I45,0) -> 0.7780635 | K24: =IFERROR(AVERAGE(C24:I24),0) -> 0.58612739 | L24: =IFERROR(MEDIAN(D24:I24),0) -> 0.79010953
B25: Return on Equity% | C25: =IFERROR('Historicial Financials'!C34/SUM('Historicial Financials'!C48:C49),0) -> 0.041555634 | D25: =IFERROR('Historicial Financials'!D34/SUM('Historicial Financials'!D48:D49),0) -> -0.28636349 | E25: =IFERROR('Historicial Financials'!E34/SUM('Historicial Financials'!E48:E49),0) -> -0.059258735 | F25: =IFERROR('Historicial Financials'!F34/SUM('Historicial Financials'!F48:F49),0) -> 0.10779307 | G25: =IFERROR('Historicial Financials'!G34/SUM('Historicial Financials'!G48:G49),0) -> 0.1140499 | H25: =IFERROR('Historicial Financials'!H34/SUM('Historicial Financials'!H48:H49),0) -> 0.12296082 | I25: =IFERROR('Historicial Financials'!I34/SUM('Historicial Financials'!I48:I49),0) -> 0.11705302 | K25: =IFERROR(AVERAGE(C25:I25),0) -> 0.022541461 | L25: =IFERROR(MEDIAN(D25:I25),0) -> 0.11092149
B26: Self Sustained Growth Rate | C26: =IFERROR(C24*C25,0) -> 0.034583967 | D26: =IFERROR(D24*D25,0) -> 0 | E26: =IFERROR(E24*E25,0) -> 0 | F26: =IFERROR(F24*F25,0) -> 0.092521698 | G26: =IFERROR(G24*G25,0) -> 0.091485762 | H26: =IFERROR(H24*H25,0) -> 0.10231726 | I26: =IFERROR(I24*I25,0) -> 0.091074685 | K26: =IFERROR(AVERAGE(C26:I26),0) -> 0.058854768 | L26: =IFERROR(MEDIAN(D26:I26),0) -> 0.091280224
B27: Interest Coverage Ratio | C27: =IFERROR(('Historicial Financials'!C19-'Historicial Financials'!C25)/'Historicial Financials'!C22,0) -> 1.6512957 | D27: =IFERROR(('Historicial Financials'!D19-'Historicial Financials'!D25)/'Historicial Financials'!D22,0) -> -1.9149744 | E27: =IFERROR(('Historicial Financials'!E19-'Historicial Financials'!E25)/'Historicial Financials'!E22,0) -> -0.003039798 | F27: =IFERROR(('Historicial Financials'!F19-'Historicial Financials'!F25)/'Historicial Financials'!F22,0) -> 5.8822283 | G27: =IFERROR(('Historicial Financials'!G19-'Historicial Financials'!G25)/'Historicial Financials'!G22,0) -> 7.7432113 | H27: =IFERROR(('Historicial Financials'!H19-'Historicial Financials'!H25)/'Historicial Financials'!H22,0) -> 10.803196 | I27: =IFERROR(('Historicial Financials'!I19-'Historicial Financials'!I25)/'Historicial Financials'!I22,0) -> 11.703817 | K27: =IFERROR(AVERAGE(C27:I27),0) -> 5.1236764 | L27: =IFERROR(MEDIAN(D27:I27),0) -> 6.8127198
B29: Debtor Turnover Ratio | C29: =IFERROR('Historicial Financials'!C7/'Historicial Financials'!C60,0) -> 15.389077 | D29: =IFERROR('Historicial Financials'!D7/'Historicial Financials'!D60,0) -> 7.1650291 | E29: =IFERROR('Historicial Financials'!E7/'Historicial Financials'!E60,0) -> 11.969218 | F29: =IFERROR('Historicial Financials'!F7/'Historicial Financials'!F60,0) -> 13.013574 | G29: =IFERROR('Historicial Financials'!G7/'Historicial Financials'!G60,0) -> 14.206334 | H29: =IFERROR('Historicial Financials'!H7/'Historicial Financials'!H60,0) -> 12.805033 | I29: =IFERROR('Historicial Financials'!I7/'Historicial Financials'!I60,0) -> 13.330976 | K29: =IFERROR(AVERAGE(C29:I29),0) -> 12.554177 | L29: =IFERROR(MEDIAN(D29:I29),0) -> 12.909303
B30: Creditor Turnover Ratio | C30: =IFERROR('Historicial Financials'!C7/'Historicial Financials'!C51,0) -> 1.7271077 | D30: =IFERROR('Historicial Financials'!D7/'Historicial Financials'!D51,0) -> 0.69454868 | E30: =IFERROR('Historicial Financials'!E7/'Historicial Financials'!E51,0) -> 1.489444 | F30: =IFERROR('Historicial Financials'!F7/'Historicial Financials'!F51,0) -> 2.4298369 | G30: =IFERROR('Historicial Financials'!G7/'Historicial Financials'!G51,0) -> 2.6642958 | H30: =IFERROR('Historicial Financials'!H7/'Historicial Financials'!H51,0) -> 2.4724236 | I30: =IFERROR('Historicial Financials'!I7/'Historicial Financials'!I51,0) -> 2.236724 | K30: =IFERROR(AVERAGE(C30:I30),0) -> 1.9591972 | L30: =IFERROR(MEDIAN(D30:I30),0) -> 2.3332804
B31: Working Capital | C31: ='Historicial Financials'!C63/'Historicial Financials'!C51 -> 0.2705743 | D31: ='Historicial Financials'!D63/'Historicial Financials'!D51 -> 0.20563167 | E31: ='Historicial Financials'!E63/'Historicial Financials'!E51 -> 0.75245624 | F31: ='Historicial Financials'!F63/'Historicial Financials'!F51 -> 0.67295813 | G31: ='Historicial Financials'!G63/'Historicial Financials'!G51 -> 0.81809379 | H31: ='Historicial Financials'!H63/'Historicial Financials'!H51 -> 0.88042421 | I31: ='Historicial Financials'!I63/'Historicial Financials'!I51 -> 0.62507272 | K31: =AVERAGE(C31:I31) -> 0.60360158 | L31: =IFERROR(MEDIAN(D31:I31),0) -> 0.71270718
B32: Inventory Turnover Ratio | C32: =IFERROR('Historicial Financials'!C10/'Historicial Financials'!C61,0) -> 31.483923 | D32: =IFERROR('Historicial Financials'!D10/AVERAGE('Historicial Financials'!D61,'Historicial Financials'!C61),0) -> 16.868787 | E32: =IFERROR('Historicial Financials'!E10/AVERAGE('Historicial Financials'!E61,'Historicial Financials'!D61),0) -> 22.81493 | F32: =IFERROR('Historicial Financials'!F10/AVERAGE('Historicial Financials'!F61,'Historicial Financials'!E61),0) -> 32.471624 | G32: =IFERROR('Historicial Financials'!G10/AVERAGE('Historicial Financials'!G61,'Historicial Financials'!F61),0) -> 34.47782 | H32: =IFERROR('Historicial Financials'!H10/AVERAGE('Historicial Financials'!H61,'Historicial Financials'!G61),0) -> 34.907864 | I32: =IFERROR('Historicial Financials'!I10/AVERAGE('Historicial Financials'!I61,'Historicial Financials'!H61),0) -> 35.642987 | K32: =IFERROR(AVERAGE(C32:I32),0) -> 29.809705 | L32: =IFERROR(MEDIAN(D32:I32),0) -> 33.474722
B33: Fixed Assets Turnover Ratio | C33: =IFERROR('Historicial Financials'!C7/'Historicial Financials'!C54,0) -> 0.55381847 | D33: =IFERROR('Historicial Financials'!D7/'Historicial Financials'!D54,0) -> 0.1866812 | E33: =IFERROR('Historicial Financials'!E7/'Historicial Financials'!E54,0) -> 0.36317249 | F33: =IFERROR('Historicial Financials'!F7/'Historicial Financials'!F54,0) -> 0.65882976 | G33: =IFERROR('Historicial Financials'!G7/'Historicial Financials'!G54,0) -> 0.72693619 | H33: =IFERROR('Historicial Financials'!H7/'Historicial Financials'!H54,0) -> 0.76336349 | I33: =IFERROR('Historicial Financials'!I7/'Historicial Financials'!I54,0) -> 0.79354401 | K33: =IFERROR(AVERAGE(C33:I33),0) -> 0.57804937 | L33: =IFERROR(MEDIAN(D33:I33),0) -> 0.69288297
B34: Capital Turnover Ratio | C34: =IFERROR('Historicial Financials'!C7/SUM('Historicial Financials'!C48:C49),0) -> 1.0244055 | D34: =IFERROR('Historicial Financials'!D7/SUM('Historicial Financials'!D48:D49),0) -> 0.43173521 | E34: =IFERROR('Historicial Financials'!E7/SUM('Historicial Financials'!E48:E49),0) -> 0.43275443 | F34: =IFERROR('Historicial Financials'!F7/SUM('Historicial Financials'!F48:F49),0) -> 0.72788012 | G34: =IFERROR('Historicial Financials'!G7/SUM('Historicial Financials'!G48:G49),0) -> 0.71576615 | H34: =IFERROR('Historicial Financials'!H7/SUM('Historicial Financials'!H48:H49),0) -> 0.74677507 | I34: =IFERROR('Historicial Financials'!I7/SUM('Historicial Financials'!I48:I49),0) -> 0.7423387 | K34: =IFERROR(AVERAGE(C34:I34),0) -> 0.68880788 | L34: =IFERROR(MEDIAN(D34:I34),0) -> 0.72182314
B36: Debtor Days | C36: =IFERROR(365/C29,0) -> 23.718122 | D36: =IFERROR(365/D29,0) -> 50.941873 | E36: =IFERROR(365/E29,0) -> 30.494892 | F36: =IFERROR(365/F29,0) -> 28.047638 | G36: =IFERROR(365/G29,0) -> 25.692765 | H36: =IFERROR(365/H29,0) -> 28.504417 | I36: =IFERROR(365/I29,0) -> 27.379841 | K36: =IFERROR(AVERAGE(C36:I36),0) -> 30.682792 | L36: =IFERROR(MEDIAN(D36:I36),0) -> 28.276027
B37: Payable Days | C37: =IFERROR(365/C30,0) -> 211.33598 | D37: =IFERROR(365/D30,0) -> 525.52112 | E37: =IFERROR(365/E30,0) -> 245.05788 | F37: =IFERROR(365/F30,0) -> 150.21585 | G37: =IFERROR(365/G30,0) -> 136.9968 | H37: =IFERROR(365/H30,0) -> 147.62842 | I37: =IFERROR(365/I30,0) -> 163.18509 | K37: =IFERROR(AVERAGE(C37:I37),0) -> 225.70588 | L37: =IFERROR(MEDIAN(D37:I37),0) -> 156.70047
B38: Inventory Days | C38: =IFERROR(365/C32,0) -> 11.593219 | D38: =IFERROR(365/D32,0) -> 21.637597 | E38: =IFERROR(365/E32,0) -> 15.998296 | F38: =IFERROR(365/F32,0) -> 11.240583 | G38: =IFERROR(365/G32,0) -> 10.586516 | H38: =IFERROR(365/H32,0) -> 10.456097 | I38: =IFERROR(365/I32,0) -> 10.240444 | K38: =IFERROR(AVERAGE(C38:I38),0) -> 13.107536 | L38: =IFERROR(MEDIAN(D38:I38),0) -> 10.91355
B39: Cash Conversion Cycle | C39: =IFERROR(SUM(C36,C38)-C37,0) -> -176.02464 | D39: =IFERROR(SUM(D36,D38)-D37,0) -> -452.94165 | E39: =IFERROR(SUM(E36,E38)-E37,0) -> -198.56469 | F39: =IFERROR(SUM(F36,F38)-F37,0) -> -110.92763 | G39: =IFERROR(SUM(G36,G38)-G37,0) -> -100.71752 | H39: =IFERROR(SUM(H36,H38)-H37,0) -> -108.66791 | I39: =IFERROR(SUM(I36,I38)-I37,0) -> -125.5648 | K39: =IFERROR(AVERAGE(C39:I39),0) -> -181.91555 | L39: =IFERROR(MEDIAN(D39:I39),0) -> -118.24621
B41: CFO/Sales | C41: =IFERROR('Historicial Financials'!C75/'Historicial Financials'!C7,0) -> 0.1897767 | D41: =IFERROR('Historicial Financials'!D75/'Historicial Financials'!D7,0) -> -0.25076818 | E41: =IFERROR('Historicial Financials'!E75/'Historicial Financials'!E7,0) -> 0.25914365 | F41: =IFERROR('Historicial Financials'!F75/'Historicial Financials'!F7,0) -> 0.28279268 | G41: =IFERROR('Historicial Financials'!G75/'Historicial Financials'!G7,0) -> 0.29119114 | H41: =IFERROR('Historicial Financials'!H75/'Historicial Financials'!H7,0) -> 0.25700279 | I41: =IFERROR('Historicial Financials'!I75/'Historicial Financials'!I7,0) -> 0.24842041 | K41: =IFERROR(AVERAGE(C41:I41),0) -> 0.18250845 | L41: =IFERROR(MEDIAN(D41:I41),0) -> 0.25807322
B42: CFO/Total Asset | C42: =IFERROR('Historicial Financials'!C75/'Historicial Financials'!C64,0) -> 0.074027073 | D42: =IFERROR('Historicial Financials'!D75/'Historicial Financials'!D64,0) -> -0.034544097 | E42: =IFERROR('Historicial Financials'!E75/'Historicial Financials'!E64,0) -> 0.060913518 | F42: =IFERROR('Historicial Financials'!F75/'Historicial Financials'!F64,0) -> 0.12159526 | G42: =IFERROR('Historicial Financials'!G75/'Historicial Financials'!G64,0) -> 0.13377749 | H42: =IFERROR('Historicial Financials'!H75/'Historicial Financials'!H64,0) -> 0.12159414 | I42: =IFERROR('Historicial Financials'!I75/'Historicial Financials'!I64,0) -> 0.11903632 | K42: =IFERROR(AVERAGE(C42:I42),0) -> 0.085199958 | L42: =IFERROR(MEDIAN(D42:I42),0) -> 0.12031523
B43: CFO/Total Debt | C43: =IFERROR('Historicial Financials'!C75/'Historicial Financials'!C50,0) -> 0.1881896 | D43: =IFERROR('Historicial Financials'!D75/'Historicial Financials'!D50,0) -> -0.071579626 | E43: =IFERROR('Historicial Financials'!E75/'Historicial Financials'!E50,0) -> 0.20371052 | F43: =IFERROR('Historicial Financials'!F75/'Historicial Financials'!F50,0) -> 0.52341343 | G43: =IFERROR('Historicial Financials'!G75/'Historicial Financials'!G50,0) -> 0.72033418 | H43: =IFERROR('Historicial Financials'!H75/'Historicial Financials'!H50,0) -> 0.69449173 | I43: =IFERROR('Historicial Financials'!I75/'Historicial Financials'!I50,0) -> 0.84856604 | K43: =IFERROR(AVERAGE(C43:I43),0) -> 0.44387512 | L43: =IFERROR(MEDIAN(D43:I43),0) -> 0.60895258

Sheet Forecasting
B1: Assumption For DCF
B3: Particulars | C3: ='Data Sheet'!G16 -> 44651 | D3: ='Data Sheet'!H16 -> 45016 | E3: ='Data Sheet'!I16 -> 45382 | F3: ='Data Sheet'!J16 -> 45747 | G3: ='Data Sheet'!K16 -> 46112 | H3: =G3+365 -> 46477 | I3: =H3+365 -> 46842 | J3: =I3+365 -> 47207 | K3: =J3+365 -> 47572 | L3: =K3+365 -> 47937
B4: Sales | C4: ='Data Sheet'!G17 -> 3056.22 | D4: ='Data Sheet'!H17 -> 5809.91 | E4: ='Data Sheet'!I17 -> 6768.75 | F4: ='Data Sheet'!J17 -> 8334.54 | G4: ='Data Sheet'!K17 -> 9689.22 | H4: =G4*1.1 -> 10658.142 | I4: =H4*1.1 -> 11723.956 | J4: =I4*1.1 -> 12896.352 | K4: =J4*1.1 -> 14185.987 | L4: =K4*1.1 -> 15604.586
B5: Sales Growth | C5: ='Historicial Financials'!E8 -> 0.94026004 | D5: ='Historicial Financials'!F8 -> 0.90101171 | E5: ='Historicial Financials'!G8 -> 0.16503526 | F5: ='Historicial Financials'!H8 -> 0.23132632 | G5: ='Historicial Financials'!I8 -> 0.16253806 | H5: =H4/G4-1 -> 0.1 | I5: =I4/H4-1 -> 0.1 | J5: =J4/I4-1 -> 0.1 | K5: =K4/J4-1 -> 0.1 | L5: =L4/K4-1 -> 0.1
B6: EBITDA | C6: ='Historicial Financials'!E19 -> 404.75 | D6: ='Historicial Financials'!F19 -> 1804.56 | E6: ='Historicial Financials'!G19 -> 2159.51 | F6: ='Historicial Financials'!H19 -> 2769.33 | G6: ='Historicial Financials'!I19 -> 3195.8 | H6: =H4*0.35 -> 3730.3497 | I6: =I4*0.35 -> 4103.3847 | J6: =J4*0.35 -> 4513.7231 | K6: =K4*0.35 -> 4965.0955 | L6: =L4*0.35 -> 5461.605
B7: EBITDA Margin | C7: ='Historicial Financials'!E20 -> 0.13243484 | D7: ='Historicial Financials'!F20 -> 0.31060034 | E7: ='Historicial Financials'!G20 -> 0.31904118 | F7: ='Historicial Financials'!H20 -> 0.33227149 | G7: ='Historicial Financials'!I20 -> 0.32983047 | H7: =H6/H4 -> 0.35 | I7: =I6/I4 -> 0.35 | J7: =J6/J4 -> 0.35 | K7: =K6/K4 -> 0.35 | L7: =L6/L4 -> 0.35
B8: D&A | C8: ='Historicial Financials'!E25 -> 406.05 | D8: ='Historicial Financials'!F25 -> 416.06 | E8: ='Historicial Financials'!G25 -> 454.3 | F8: ='Historicial Financials'!H25 -> 518.16 | G8: ='Historicial Financials'!I25 -> 605.16 | H8: =H4*$G$9 -> 665.676 | I8: =I4*$G$9 -> 732.2436 | J8: =J4*$G$9 -> 805.46796 | K8: =K4*$G$9 -> 886.01476 | L8: =L4*$G$9 -> 974.61623
B9: D&A % Sales | C9: ='Historicial Financials'!E26 -> 0.1328602 | D9: ='Historicial Financials'!F26 -> 0.071612125 | E9: ='Historicial Financials'!G26 -> 0.067117267 | F9: ='Historicial Financials'!H26 -> 0.062170198 | G9: ='Historicial Financials'!I26 -> 0.06245704 | H9: =H8/H4 -> 0.06245704 | I9: =I8/I4 -> 0.06245704 | J9: =J8/J4 -> 0.06245704 | K9: =K8/K4 -> 0.06245704 | L9: =L8/L4 -> 0.06245704
B10: EBIT | C10: =C6-C8 -> -1.3 | D10: =D6-D8 -> 1388.5 | E10: =E6-E8 -> 1705.21 | F10: =F6-F8 -> 2251.17 | G10: =G6-G8 -> 2590.64 | H10: =H6-H8 -> 3064.6737 | I10: =I6-I8 -> 3371.1411 | J10: =J6-J8 -> 3708.2552 | ... L10: =L6-L8 -> 4486.9888
B11: Tax Rate | C11: 0.25 | D11: 0.25 | E11: 0.25 | F11: 0.25 | G11: 0.25 | H11: 0.25 | I11: 0.25 | J11: 0.25 | K11: 0.25 | L11: 0.25
B12: NOPAT | C12: =C10*(1-C11) -> -0.975 | D12: =D10*(1-D11) -> 1041.375 | E12: =E10*(1-E11) -> 1278.9075 | F12: =F10*(1-F11) -> 1688.3775 | G12: =G10*(1-G11) -> 1942.98 | H12: =H10*(1-H11) -> 2298.5053 | I12: =I10*(1-I11) -> 2528.3558 | J12: =J10*(1-J11) -> 2781.1914 | ... L12: =L10*(1-L11) -> 3365.2416
B13: Capex | C13: =IFERROR(('Historicial Financials'!E78*-1)-'Historicial Financials'!E79,0) -> 285 | D13: =IFERROR(('Historicial Financials'!F78*-1)-'Historicial Financials'!F79,0) -> 428 | E13: =IFERROR(('Historicial Financials'!G78*-1)-'Historicial Financials'!G79,0) -> 633 | F13: =IFERROR(('Historicial Financials'!H78*-1)-'Historicial Financials'!H79,0) -> 1062 | G13: =IFERROR(('Historicial Financials'!I78*-1)-'Historicial Financials'!I79,0) -> 1028 | H13: =H4*0.1 -> 1065.8142 | I13: =I4*0.1 -> 1172.3956 | J13: =J4*0.1 -> 1289.6352 | K13: =K4*0.1 -> 1418.5987 | L13: =L4*0.1 -> 1560.4586
B14: Capex % of sales | C14: =C13/C4 -> 0.093252449 | D14: =D13/D4 -> 0.073667234 | E14: =E13/E4 -> 0.093518006 | F14: =F13/F4 -> 0.12742155 | G14: =G13/G4 -> 0.10609729 | H14: =H13/H4 -> 0.1 | I14: =I13/I4 -> 0.1 | J14: =J13/J4 -> 0.1 | ... L14: =L13/L4 -> 0.1
B15: Net Working Capital | C15: =C30 -> -76 | D15: =D30 -> -2 | E15: =E30 -> -6 | F15: =F30 -> 86 | G15: =G30 -> 58 | H15: =H4*$C$31 -> -20.875987 | I15: =I4*$C$31 -> -22.963586 | J15: =J4*$C$31 -> -25.259945 | K15: =K4*$C$31 -> -27.785939 | L15: =L4*$C$31 -> -30.564533
B16: NWC % of sales | C16: =C15/C4 -> -0.02486732 | D16: =D15/D4 -> -0.00034423941 | E16: =E15/E4 -> -0.00088642659 | F16: =F15/F4 -> 0.010318506 | G16: =G15/G4 -> 0.005986034 | H16: =H15/H4 -> -0.0019586892 | I16: =I15/I4 -> -0.0019586892 | J16: =J15/J4 -> -0.0019586892 | ... L16: =L15/L4 -> -0.0019586892
B17: FCFF | C17: =(C12+C8)-(C13+C15) -> 196.075 | D17: =(D12+D8)-(D13+D15) -> 1031.435 | E17: =(E12+E8)-(E13+E15) -> 1106.2075 | F17: =(F12+F8)-(F13+F15) -> 1058.5375 | G17: =(G12+G8)-(G13+G15) -> 1462.14 | H17: =(H12+H8)-(H13+H15) -> 1919.2431 | I17: =(I12+I8)-(I13+I15) -> 2111.1674 | J17: =(J12+J8)-(J13+J15) -> 2322.2841 | ... L17: =(L12+L8)-(L13+L15) -> 2809.9638
B19: Notes
B20: Sales Growth | C20: 0.1 | D20: (From Mgnt Discussion , Firm's Revenue target)
B21: EBITDA Margin | C21: 0.35 | D21: (From Mgnt Discussion , To maintain Margin of 35%)
B22: D&A | C22: 0.0625 | D22: (Assume to be constant)
B23: Tax Rate | C23: 0.25 | D23: (Assume as per the Indian Corporate Tax)
